Workbook

Sheet الرئيسيــة
A1: ت | B1: الرقم الوظيفي | C1: الاسم الكامل | D1: العنوان الوظيفي | E1: التحصيل الدراسي | F1: الدرجة | G1: المرحلة | I1: الراتب القديم | K1: المرحلة الجديدة | M1: الراتب الجديد | P1: تاريخ الاستحقاق القديم | Q1: تاريخ الاستحقاق القادم | R1: تاريخ الاستحقاق | S1: تنبيه العلاوة | W1: كتب الشكر | X1: عدد كتب الشكر | Y1: رقم وتاريخ الكتب | Z1: خدمة المدورة | AC1: اجازة بدون راتب / غيابات | AD1: لفت نظر / امومة | AE1: انذار | AF1: توبيخ | AI1: رقم وتاريخ العقوبات | AJ1: الملاحظات | AK1: نوع الملاك | AL1: الملاحظات الخاصة | AM1: password_hash | AN1: must_change_password | AO1: first_login | AP1: الجنس
A2: 1 | B2: 100544268 | C2: ابراهيم نذير ابراهيم ابراهيم | D2: رئيس مهندسين اقدم اول | E2: بكالوريوس هندسة | F2: 1 | G2: 2 | H2: =G2&"/"&F2 -> 2/1 | I2: =IF(G2="","",VLOOKUP(H2,ورقة1!$A$1:$B$240,2,0)) -> 930 | J2: =F2 -> 1 | K2: =IF(G2="","",G2+1) -> 3 | L2: =K2&"/"&J2 -> 3/1 | M2: =IF(K2="","",VLOOKUP(L2,ورقة1!$A$1:$B$240,2,0)) -> 950 | N2: =Z2+(AA2*30)+(AB2*365) -> 0 | O2: =#REF!+(#REF!*30)+#REF!*365 -> #REF! | P2: 45683 | Q2: =IF(P2="","",P2+365) -> 46048 | R2: =IF(P2="","",EDATE(P2,12+AG2)+AC2-N2) -> 46048 | S2: =IF(P2="","",IF(T2=TRUE,"يستحق العلاوة",IF(V2=TRUE,"قريبا يستحق العلاوة"," "))) -> يستحق العلاوة | T2: =AND(MONTH(U2)=MONTH(R2),YEAR(U2)=YEAR(R2)) -> TRUE | U2: =TODAY() -> 46035 | V2: =AND(R2-U2<30,U2<R2) -> TRUE | AG2: =(((AD2*3)+(AE2*6)+(AF2*12))-AH2) -> 0 | AH2: =W2+X2 -> 0 | AK2: ملاك قديم | AL2: تم الترقية 20205 | AM2: scrypt:32768:8:1$wlNylYwVBYjqMhbQ$94a447fee912c76e7e0755e58ff154e3b49eb0e73f7c4963e275ed4881e884fbb916e0dd9dd3ddebfab1220c5c030bf6433245f4553e790ddb4cd86c02a9d0b4 | AN2: 1 | AO2: 1 | AP2: ذكر
A3: 2 | B3: 100271340 | C3: انتصار عباس خضير عباس العزاوي | D3: مدير تدقيق اقدم اول | E3: بكالوريوس علوم مالية ومصرفية | F3: 1 | G3: 20 | H3: =G3&"/"&F3 -> 20/1 | I3: =IF(G3="","",VLOOKUP(H3,ورقة1!$A$1:$B$240,2,0)) -> 1290 | J3: =F3 -> 1 | K3: =IF(G3="","",G3+1) -> 21 | L3: =K3&"/"&J3 -> 21/1 | M3: =IF(K3="","",VLOOKUP(L3,ورقة1!$A$1:$B$240,2,0)) -> #N/A | N3: =Z3+(AA3*30)+(AB3*365) -> 0 | O3: =#REF!+(#REF!*30)+#REF!*365 -> #REF! | P3: 45803 | Q3: =IF(P3="","",P3+365) -> 46168 | R3: =IF(P3="","",EDATE(P3,12+AG3)+AC3-N3) -> 46168 | S3: =IF(P3="","",IF(T3=TRUE,"يستحق العلاوة",IF(V3=TRUE,"قريبا يستحق العلاوة"," "))) | T3: =AND(MONTH(U3)=MONTH(R3),YEAR(U3)=YEAR(R3)) -> FALSE | U3: =TODAY() -> 46035 | V3: =AND(R3-U3<30,U3<R3) -> FALSE | AG3: =(((AD3*3)+(AE3*6)+(AF3*12))-AH3) -> 0 | AH3: =W3+X3 -> 0 | AK3: ملاك قديم | AM3: scrypt:32768:8:1$FhOf25cqgVpFNjiP$3592b4bc6a802702d8823d603a3add2852966dc0f3f6c02cfcf260227c3e03aaa0a1b2357f7a1114523d57ef4d53dc57eacb44bc2e2ff57be3eb4f2870ecb772 | AN3: 1 | AO3: 1 | AP3: انثى
A4: 3 | B4: 100540860 | C4: خالد كاظم عبدالكريم | D4: رئيس مهندسين اقدم اول | E4: بكالوريوس هندسة ميكانيك | F4: 1 | G4: 5 | H4: =G4&"/"&F4 -> 5/1 | I4: =IF(G4="","",VLOOKUP(H4,ورقة1!$A$1:$B$240,2,0)) -> 990 | J4: =F4 -> 1 | K4: =IF(G4="","",G4+1) -> 6 | L4: =K4&"/"&J4 -> 6/1 | M4: =IF(K4="","",VLOOKUP(L4,ورقة1!$A$1:$B$240,2,0)) -> 1010 | N4: =Z4+(AA4*30)+(AB4*365) -> 0 | O4: =#REF!+(#REF!*30)+#REF!*365 -> #REF! | P4: 46017 | Q4: =IF(P4="","",P4+365) -> 46382 | R4: =IF(P4="","",EDATE(P4,12+AG4)+AC4-N4) -> 46382 | S4: =IF(P4="","",IF(T4=TRUE,"يستحق العلاوة",IF(V4=TRUE,"قريبا يستحق العلاوة"," "))) | T4: =AND(MONTH(U4)=MONTH(R4),YEAR(U4)=YEAR(R4)) -> FALSE | U4: =TODAY() -> 46035 | V4: =AND(R4-U4<30,U4<R4) -> FALSE | AG4: =(((AD4*3)+(AE4*6)+(AF4*12))-AH4) -> 0 | AH4: =W4+X4 -> 0 | AK4: ملاك قديم | AL4: مدير موقع عبدالعباس | AM4: scrypt:32768:8:1$tvf2b9JhJJWpaTPJ$fe0709855f8e3afb91318f170481535fa481e8da73a867fbdf7b49710a5e3b64634f5ce9469138e0a008e33442886f31027818f51c58567d429539f9aee59107 | AN4: 1 | AO4: 1 | AP4: ذكر
A5: 4 | B5: 100269613 | C5: زياد حسان بديع محمود النائب | D5: رئيس مهندسين اقدم اول | E5: بكالوريوس هندسة مكائن ومعدات | F5: 1 | G5: 5 | H5: =G5&"/"&F5 -> 5/1 | I5: =IF(G5="","",VLOOKUP(H5,ورقة1!$A$1:$B$240,2,0)) -> 990 | J5: =F5 -> 1 | K5: =IF(G5="","",G5+1) -> 6 | L5: =K5&"/"&J5 -> 6/1 | M5: =IF(K5="","",VLOOKUP(L5,ورقة1!$A$1:$B$240,2,0)) -> 1010 | N5: =Z5+(AA5*30)+(AB5*365) -> 0 | O5: =#REF!+(#REF!*30)+#REF!*365 -> #REF! | P5: 45834 | Q5: =IF(P5="","",P5+365) -> 46199 | R5: =IF(P5="","",EDATE(P5,12+AG5)+AC5-N5) -> 46168 | S5: =IF(P5="","",IF(T5=TRUE,"يستحق العلاوة",IF(V5=TRUE,"قريبا يستحق العلاوة"," "))) | T5: =AND(MONTH(U5)=MONTH(R5),YEAR(U5)=YEAR(R5)) -> FALSE | U5: =TODAY() -> 46035 | V5: =AND(R5-U5<30,U5<R5) -> FALSE | X5: 1 | Y5: 52711في 6/10/2025 | AG5: =(((AD5*3)+(AE5*6)+(AF5*12))-AH5) -> -1 | AH5: =W5+X5 -> 1 | AK5: ملاك قديم | AM5: scrypt:32768:8:1$IXveM0nQABCtgWff$a9ea3c6058decfcb7cff9be43029c398880a6d6a8fb0fa468ba83b4e18a5f406bc261534efc9c859a5ee6eb3b1c66432a6c7f9189d3101fcff2db690f81627f4 | AN5: 1 | AO5: 1 | AP5: ذكر
A6: 5 | B6: 100273656 | C6: عدنان سلمان داود كريم البالوي | D6: رئيس مهندسين أقدم اول | E6: بكالوريوس هندسة الكترونيك | F6: 1 | G6: 7 | H6: =G6&"/"&F6 -> 7/1 | I6: =IF(G6="","",VLOOKUP(H6,ورقة1!$A$1:$B$240,2,0)) -> 1030 | J6: =F6 -> 1 | K6: =IF(G6="","",G6+1) -> 8 | L6: =K6&"/"&J6 -> 8/1 | M6: =IF(K6="","",VLOOKUP(L6,ورقة1!$A$1:$B$240,2,0)) -> 1050 | N6: =Z6+(AA6*30)+(AB6*365) -> 0 | O6: =#REF!+(#REF!*30)+#REF!*365 -> #REF! | P6: 45834 | Q6: =IF(P6="","",P6+365) -> 46199 | R6: =IF(P6="","",EDATE(P6,12+AG6)+AC6-N6) -> 46138 | S6: =IF(P6="","",IF(T6=TRUE,"يستحق العلاوة",IF(V6=TRUE,"قريبا يستحق العلاوة"," "))) | T6: =AND(MONTH(U6)=MONTH(R6),YEAR(U6)=YEAR(R6)) -> FALSE | U6: =TODAY() -> 46035 | V6: =AND(R6-U6<30,U6<R6) -> FALSE | X6: 2 | Y6: 52711في 6/10/2025 60534في 4/11/2025 | AG6: =(((AD6*3)+(AE6*6)+(AF6*12))-AH6) -> -2 | AH6: =W6+X6 -> 2 | AK6: ملاك قديم | AM6: scrypt:32768:8:1$oGhUu9Yf3ruBWv7K$02d9783f5b54ae0d154f17b8b905bf420942d4296ebe7f0af4d9de1f6f4265af88b236019de4c219570096cdd3b32c725bd25e9e0935a78adb51d3929096a8e3 | AN6: 1 | AO6: 1 | AP6: ذكر
A7: 6 | B7: 100270631 | C7: عصام محسن محمود صالح الموسوي | D7: رئيس مهندسين تقني اقدم اول | E7: بكالوريوس هندسة تقنيات الحاسبات | F7: 1 | G7: 17 | H7: =G7&"/"&F7 -> 17/1 | I7: =IF(G7="","",VLOOKUP(H7,ورقة1!$A$1:$B$240,2,0)) -> 1230 | J7: =F7 -> 1 | K7: =IF(G7="","",G7+1) -> 18 | L7: =K7&"/"&J7 -> 18/1 | M7: =IF(K7="","",VLOOKUP(L7,ورقة1!$A$1:$B$240,2,0)) -> 1250 | N7: =Z7+(AA7*30)+(AB7*365) -> 0 | O7: =#REF!+(#REF!*30)+#REF!*365 -> #REF! | P7: 45864 | Q7: =IF(P7="","",P7+365) -> 46229 | R7: =IF(P7="","",EDATE(P7,12+AG7)+AC7-N7) -> 46229 | S7: =IF(P7="","",IF(T7=TRUE,"يستحق العلاوة",IF(V7=TRUE,"قريبا يستحق العلاوة"," "))) | T7: =AND(MONTH(U7)=MONTH(R7),YEAR(U7)=YEAR(R7)) -> FALSE | U7: =TODAY() -> 46035 | V7: =AND(R7-U7<30,U7<R7) -> FALSE | AG7: =(((AD7*3)+(AE7*6)+(AF7*12))-AH7) -> 0 | AH7: =W7+X7 -> 0 | AK7: ملاك قديم | AM7: scrypt:32768:8:1$1ywG5oqer2oBBgVd$1ff461f4c0b73d14908ec71e1c6c4e12a270dd258d7b01f1e4a6cb9cf328619f7c6b99f9d1997398fbac5709671705d1814ea3d385f7b6c46a4e3e1319009c59 | AN7: 1 | AO7: 1 | AP7: ذكر
A8: 7 | B8: 100270305 | C8: فاضل علك خضير | D8: رئيس مهندسين تقني اقدم اول | E8: بكالوريوس هندسة تقنيات الكهرباء | F8: 1 | G8: 14 | H8: =G8&"/"&F8 -> 14/1 | I8: =IF(G8="","",VLOOKUP(H8,ورقة1!$A$1:$B$240,2,0)) -> 1170 | J8: =F8 -> 1 | K8: =IF(G8="","",G8+1) -> 15 | L8: =K8&"/"&J8 -> 15/1 | M8: =IF(K8="","",VLOOKUP(L8,ورقة1!$A$1:$B$240,2,0)) -> 1190 | N8: =Z8+(AA8*30)+(AB8*365) -> 0 | O8: =#REF!+(#REF!*30)+#REF!*365 -> #REF! | P8: 45864 | Q8: =IF(P8="","",P8+365) -> 46229 | R8: =IF(P8="","",EDATE(P8,12+AG8)+AC8-N8) -> 46229 | S8: =IF(P8="","",IF(T8=TRUE,"يستحق العلاوة",IF(V8=TRUE,"قريبا يستحق العلاوة"," "))) | T8: =AND(MONTH(U8)=MONTH(R8),YEAR(U8)=YEAR(R8)) -> FALSE | U8: =TODAY() -> 46035 | V8: =AND(R8-U8<30,U8<R8) -> FALSE | AG8: =(((AD8*3)+(AE8*6)+(AF8*12))-AH8) -> 0 | AH8: =W8+X8 -> 0 | AM8: scrypt:32768:8:1$vkoZZdbxUvDA4C9z$d4fc95faf7a57f1d69a91acfb991777ef7dc88d3aa9860c3fe8e431e1893da000f17c7e55301858417989ac996a617e74ceb43dfc32a32d9947d37c599782937 | AN8: 1 | AO8: 1
A9: 8 | B9: 100269600 | C9: ياسر اكرم داود سلمان القيسي | D9: رئيس مهندسين اقدم اول | E9: بكالوريوس هندسة ميكانيك | F9: 1 | G9: 9 | H9: =G9&"/"&F9 -> 9/1 | I9: =IF(G9="","",VLOOKUP(H9,ورقة1!$A$1:$B$240,2,0)) -> 1070 | J9: =F9 -> 1 | K9: =IF(G9="","",G9+1) -> 10 | L9: =K9&"/"&J9 -> 10/1 | M9: =IF(K9="","",VLOOKUP(L9,ورقة1!$A$1:$B$240,2,0)) -> 1090 | N9: =Z9+(AA9*30)+(AB9*365) -> 0 | O9: =#REF!+(#REF!*30)+#REF!*365 -> #REF! | P9: 45773 | Q9: =IF(P9="","",P9+365) -> 46138 | R9: =IF(P9="","",EDATE(P9,12+AG9)+AC9-N9) -> 46048 | S9: =IF(P9="","",IF(T9=TRUE,"يستحق العلاوة",IF(V9=TRUE,"قريبا يستحق العلاوة"," "))) -> يستحق العلاوة | T9: =AND(MONTH(U9)=MONTH(R9),YEAR(U9)=YEAR(R9)) -> TRUE | U9: =TODAY() -> 46035 | V9: =AND(R9-U9<30,U9<R9) -> TRUE | X9: 3 | Y9: 52711في 6/10/2025 60534في 4/11/2025 64852في 25/11/2025 | AG9: =(((AD9*3)+(AE9*6)+(AF9*12))-AH9) -> -3 | AH9: =W9+X9 -> 3 | AK9: ملاك قديم | AM9: scrypt:32768:8:1$x5EhMFw04n5I8ebW$5acad95d0b71168d56b484052c70bd93f9c6c488f591e6ec05909f78abae8e10d488e02c4693039d67e0c4214d5d90094bc9c7b9fc280d7838e6ea07acb5a2d4 | AN9: 1 | AO9: 1 | AP9: ذكر
A10: 9 | B10: 100269163 | C10: ياسر صبحي محمد عباس الزنكناوي | D10: رئيس مهندسين اقدم اول | E10: بكالوريوس هندسة مكائن ومعدات | F10: 1 | G10: 2 | H10: =G10&"/"&F10 -> 2/1 | I10: =IF(G10="","",VLOOKUP(H10,ورقة1!$A$1:$B$240,2,0)) -> 930 | J10: =F10 -> 1 | K10: =IF(G10="","",G10+1) -> 3 | L10: =K10&"/"&J10 -> 3/1 | M10: =IF(K10="","",VLOOKUP(L10,ورقة1!$A$1:$B$240,2,0)) -> 950 | N10: =Z10+(AA10*30)+(AB10*365) -> 0 | O10: =#REF!+(#REF!*30)+#REF!*365 -> #REF! | P10: 45757 | Q10: =IF(P10="","",P10+365) -> 46122 | R10: =IF(P10="","",EDATE(P10,12+AG10)+AC10-N10) -> 46032 | S10: =IF(P10="","",IF(T10=TRUE,"يستحق العلاوة",IF(V10=TRUE,"قريبا يستحق العلاوة"," "))) -> يستحق العلاوة | T10: =AND(MONTH(U10)=MONTH(R10),YEAR(U10)=YEAR(R10)) -> TRUE | U10: =TODAY() -> 46035 | V10: =AND(R10-U10<30,U10<R10) -> FALSE | X10: 3 | Y10: 52711في 6/10/2025 60534في 4/11/2025 65653في 26/11/2025 | AG10: =(((AD10*3)+(AE10*6)+(AF10*12))-AH10) -> -3 | AH10: =W10+X10 -> 3 | AK10: ملاك قديم | AL10: تم الترقية 2025 | AM10: scrypt:32768:8:1$9vG6gek3ZchzQTC0$46b9ad2863fb550e1648e4a5ec220a653491736ba7d9487e326142f3842e5ccb62072d8fe29063896fc97c308c1b9c12943e2e1cd84f220f8e2f2f52984e3e31 | AN10: 1 | AO10: 1 | AP10: ذكر
A11: 10 | B11: 100270376 | C11: بلاسم حسين علي محمد المشهداني | D11: مدير فني اقدم | E11: اعدادية تشغيل وحدات | F11: 2 | H11: =G11&"/"&F11 -> /2 | I11: =IF(G11="","",VLOOKUP(H11,ورقة1!$A$1:$B$240,2,0)) | J11: =F11 -> 2 | K11: =IF(G11="","",G11+1) | L11: =K11&"/"&J11 -> /2 | M11: =IF(K11="","",VLOOKUP(L11,ورقة1!$A$1:$B$240,2,0)) | N11: =Z11+(AA11*30)+(AB11*365) -> 0 | O11: =#REF!+(#REF!*30)+#REF!*365 -> #REF! | Q11: =IF(P11="","",P11+365) | R11: =IF(P11="","",EDATE(P11,12+AG11)+AC11-N11) | S11: =IF(P11="","",IF(T11=TRUE,"يستحق العلاوة",IF(V11=TRUE,"قريبا يستحق العلاوة"," "))) | T11: =AND(MONTH(U11)=MONTH(R11),YEAR(U11)=YEAR(R11)) -> #VALUE! | U11: =TODAY() -> 46035 | V11: =AND(R11-U11<30,U11<R11) -> #VALUE! | X11: 8 | Y11: 17929 في 11/3/2024 14442في 13/3/2025 18526في 14/4/2025 | AG11: =(((AD11*3)+(AE11*6)+(AF11*12))-AH11) -> -8 | AH11: =W11+X11 -> 8 | AK11: ملاك قديم | AL11: متوقف | AM11: scrypt:32768:8:1$Mo2fAT5oJX4DXcxd$387727c266721dd6fb2c1c080ed2ee57cf245f53307b946d26d6254c66185385062b3229f19d50730d775bc0703d183c34f2a97f02b44e8bb2cf344979d8b1ce | AN11: 1 | AO11: 1 | AP11: ذكر
A12: 11 | B12: 100264212 | C12: خالد ابراهيم علي ابراهيم العكيدي | D12: رئيس مهندسين اقدم | E12: بكالوريوس هندسة كيمياء | F12: 2 | G12: 2 | H12: =G12&"/"&F12 -> 2/2 | I12: =IF(G12="","",VLOOKUP(H12,ورقة1!$A$1:$B$240,2,0)) -> 740 | J12: =F12 -> 2 | K12: =IF(G12="","",G12+1) -> 3 | L12: =K12&"/"&J12 -> 3/2 | M12: =IF(K12="","",VLOOKUP(L12,ورقة1!$A$1:$B$240,2,0)) -> 757 | N12: =Z12+(AA12*30)+(AB12*365) -> 0 | O12: =#REF!+(#REF!*30)+#REF!*365 -> #REF! | P12: 45956 | Q12: =IF(P12="","",P12+365) -> 46321 | R12: =IF(P12="","",EDATE(P12,12+AG12)+AC12-N12) -> 46291 | S12: =IF(P12="","",IF(T12=TRUE,"يستحق العلاوة",IF(V12=TRUE,"قريبا يستحق العلاوة"," "))) | T12: =AND(MONTH(U12)=MONTH(R12),YEAR(U12)=YEAR(R12)) -> FALSE | U12: =TODAY() -> 46035 | V12: =AND(R12-U12<30,U12<R12) -> FALSE | X12: 1 | Y12: 52711في 6/10/2025 | AG12: =(((AD12*3)+(AE12*6)+(AF12*12))-AH12) -> -1 | AH12: =W12+X12 -> 1 | AK12: ملاك قديم | AL12: تم الترقية 2025 | AM12: scrypt:32768:8:1$0rDjsGATnwHhwI3t$102073e0251385417162fe56dbebecf9123881112316aafd872a0f1985b1e0b1ee6fd3c846985e8a2cb9163ec716cec2f44eb80c391a20426b546e688739b15e | AN12: 1 | AO12: 1 | AP12: ذكر
A13: 12 | B13: 100270628 | C13: سجى محمدعلي مهدي شلال الشرفي | D13: مدير حسابات اقدم | E13: دبلوم محاسبة | F13: 2 | G13: 9 | H13: =G13&"/"&F13 -> 9/2 | I13: =IF(G13="","",VLOOKUP(H13,ورقة1!$A$1:$B$240,2,0)) -> 859 | J13: =F13 -> 2 | K13: =IF(G13="","",G13+1) -> 10 | L13: =K13&"/"&J13 -> 10/2 | M13: =IF(K13="","",VLOOKUP(L13,ورقة1!$A$1:$B$240,2,0)) -> 876 | N13: =Z13+(AA13*30)+(AB13*365) -> 0 | O13: =#REF!+(#REF!*30)+#REF!*365 -> #REF! | P13: 45932 | Q13: =IF(P13="","",P13+365) -> 46297 | R13: =IF(P13="","",EDATE(P13,12+AG13)+AC13-N13) -> 46083 | S13: =IF(P13="","",IF(T13=TRUE,"يستحق العلاوة",IF(V13=TRUE,"قريبا يستحق العلاوة"," "))) | T13: =AND(MONTH(U13)=MONTH(R13),YEAR(U13)=YEAR(R13)) -> FALSE | U13: =TODAY() -> 46035 | V13: =AND(R13-U13<30,U13<R13) -> FALSE | X13: 7 | Y13: 47692في 16/9/2025 48879في 21/9/2025 | AG13: =(((AD13*3)+(AE13*6)+(AF13*12))-AH13) -> -7 | AH13: =W13+X13 -> 7 | AK13: ملاك قديم | AM13: scrypt:32768:8:1$cG0aNNQzR04pcGJs$80ea3244b81c973670165c96f82b3858668371f8d37ed61ead0eac408b783702cc084305c86b67cbfa011639d4c2e2dce5f0f68b70ada824a03248cde7ea7341 | AN13: 1 | AO13: 1 | AP13: انثى
A14: 13 | B14: 100269783 | C14: محمد محي حيدر زين العابدين البياتي | D14: مدير فني اقدم | E14: دبلوم كهرباء | F14: 2 | G14: 6 | H14: =G14&"/"&F14 -> 6/2 | I14: =IF(G14="","",VLOOKUP(H14,ورقة1!$A$1:$B$240,2,0)) -> 808 | J14: =F14 -> 2 | K14: =IF(G14="","",G14+1) -> 7 | L14: =K14&"/"&J14 -> 7/2 | M14: =IF(K14="","",VLOOKUP(L14,ورقة1!$A$1:$B$240,2,0)) -> 825 | N14: =Z14+(AA14*30)+(AB14*365) -> 0 | O14: =#REF!+(#REF!*30)+#REF!*365 -> #REF! | P14: 45932 | Q14: =IF(P14="","",P14+365) -> 46297 | R14: =IF(P14="","",EDATE(P14,12+AG14)+AC14-N14) -> 46297 | S14: =IF(P14="","",IF(T14=TRUE,"يستحق العلاوة",IF(V14=TRUE,"قريبا يستحق العلاوة"," "))) | T14: =AND(MONTH(U14)=MONTH(R14),YEAR(U14)=YEAR(R14)) -> FALSE | U14: =TODAY() -> 46035 | V14: =AND(R14-U14<30,U14<R14) -> FALSE | AG14: =(((AD14*3)+(AE14*6)+(AF14*12))-AH14) -> 0 | AH14: =W14+X14 -> 0 | AK14: ملاك قديم | AL14: تم الترقية 2025 | AM14: scrypt:32768:8:1$N6haQ9ksbGovQWpE$d94df79625457f5de99ca58be341b66854ea13acda5a6613c6e0b1b905307b94caa307a37cc44d4302f81ebd8d3090f7e7deca0f9d0cf279a9b9ce21c10139a9 | AN14: 1 | AO14: 1 | AP14: ذكر
A15: 14 | B15: 106313589 | C15: منير جبار مرداو فضالة | D15: مدير تدقيق اقدم | E15: بكالوريوس علوم مالية ومصرفية | F15: 2 | G15: 5 | H15: =G15&"/"&F15 -> 5/2 | I15: =IF(G15="","",VLOOKUP(H15,ورقة1!$A$1:$B$240,2,0)) -> 791 | J15: =F15 -> 2 | K15: =IF(G15="","",G15+1) -> 6 | L15: =K15&"/"&J15 -> 6/2 | M15: =IF(K15="","",VLOOKUP(L15,ورقة1!$A$1:$B$240,2,0)) -> 808 | N15: =Z15+(AA15*30)+(AB15*365) -> 0 | O15: =#REF!+(#REF!*30)+#REF!*365 -> #REF! | P15: 45992 | Q15: =IF(P15="","",P15+365) -> 46357 | R15: =IF(P15="","",EDATE(P15,12+AG15)+AC15-N15) -> 46357 | S15: =IF(P15="","",IF(T15=TRUE,"يستحق العلاوة",IF(V15=TRUE,"قريبا يستحق العلاوة"," "))) | T15: =AND(MONTH(U15)=MONTH(R15),YEAR(U15)=YEAR(R15)) -> FALSE | U15: =TODAY() -> 46035 | V15: =AND(R15-U15<30,U15<R15) -> FALSE | AG15: =(((AD15*3)+(AE15*6)+(AF15*12))-AH15) -> 0 | AH15: =W15+X15 -> 0 | AM15: scrypt:32768:8:1$kaLiSRS4B885jMLq$1e62441076555cdba2cda94fe9ef36cec6f374804a648a2425c9d4d8be4fe8496ed07ca866d1f98974c2bb7478ab8b98861ea72bc9db20c2dc7535ba854c9cd1 | AN15: 1 | AO15: 1
A16: 15 | B16: 100268595 | C16: ناطق حمد مشتت حريب الدراجي | D16: مدير فني اقدم | E16: دبلوم كهرباء | F16: 2 | G16: 9 | H16: =G16&"/"&F16 -> 9/2 | I16: =IF(G16="","",VLOOKUP(H16,ورقة1!$A$1:$B$240,2,0)) -> 859 | J16: =F16 -> 2 | K16: =IF(G16="","",G16+1) -> 10 | L16: =K16&"/"&J16 -> 10/2 | M16: =IF(K16="","",VLOOKUP(L16,ورقة1!$A$1:$B$240,2,0)) -> 876 | N16: =Z16+(AA16*30)+(AB16*365) -> 0 | O16: =#REF!+(#REF!*30)+#REF!*365 -> #REF! | P16: 45932 | Q16: =IF(P16="","",P16+365) -> 46297 | R16: =IF(P16="","",EDATE(P16,12+AG16)+AC16-N16) -> 46297 | S16: =IF(P16="","",IF(T16=TRUE,"يستحق العلاوة",IF(V16=TRUE,"قريبا يستحق العلاوة"," "))) | T16: =AND(MONTH(U16)=MONTH(R16),YEAR(U16)=YEAR(R16)) -> FALSE | U16: =TODAY() -> 46035 | V16: =AND(R16-U16<30,U16<R16) -> FALSE | AG16: =(((AD16*3)+(AE16*6)+(AF16*12))-AH16) -> 0 | AH16: =W16+X16 -> 0 | AK16: ملاك قديم | AL16: تم الترقية | AM16: scrypt:32768:8:1$jeiqxKVM3QBHWXxZ$87ee7f17b1cbce818efa593eca785cfb5f3feda8af00f73a92c9b8fea14852cb319427a916ad72ca3358e2e86c0e2565c91bb1a646176581446d544804a87946 | AN16: 1 | AO16: 1 | AP16: ذكر
A17: 16 | B17: 100270699 | C17: وسن صباح عباس محمد الشجيري | D17: رئيس مهندسين اقدم | E17: بكالوريوس هندسة كهرباء | F17: 2 | G17: 1 | H17: =G17&"/"&F17 -> 1/2 | I17: =IF(G17="","",VLOOKUP(H17,ورقة1!$A$1:$B$240,2,0)) -> 723 | J17: =F17 -> 2 | K17: =IF(G17="","",G17+1) -> 2 | L17: =K17&"/"&J17 -> 2/2 | M17: =IF(K17="","",VLOOKUP(L17,ورقة1!$A$1:$B$240,2,0)) -> 740 | N17: =Z17+(AA17*30)+(AB17*365) -> 0 | O17: =#REF!+(#REF!*30)+#REF!*365 -> #REF! | P17: 45993 | Q17: =IF(P17="","",P17+365) -> 46358 | R17: =IF(P17="","",EDATE(P17,12+AG17)+AC17-N17) -> 46358 | S17: =IF(P17="","",IF(T17=TRUE,"يستحق العلاوة",IF(V17=TRUE,"قريبا يستحق العلاوة"," "))) | T17: =AND(MONTH(U17)=MONTH(R17),YEAR(U17)=YEAR(R17)) -> FALSE | U17: =TODAY() -> 46035 | V17: =AND(R17-U17<30,U17<R17) -> FALSE | AG17: =(((AD17*3)+(AE17*6)+(AF17*12))-AH17) -> 0 | AH17: =W17+X17 -> 0 | AK17: ملاك قديم | AL17: تم الترقية 2025 | AM17: scrypt:32768:8:1$jgWU5bYvl2pfypjz$f551d2d30cde0aaa504d2aab3a18d62d91213746acb13b5fc603c045ffa7e58d2dab0b8ac1b312e752a0d63158ab47bbd339eac3844dbf9d42afc411efb6f358 | AN17: 1 | AO17: 1 | AP17: انثى
A18: 17 | B18: 100269022 | C18: ابراهيم جاسم محسن جعفر الجمالي | D18: مدير فني | E18: اعدادية خطوط وقابلوات | F18: 3 | G18: 20 | H18: =G18&"/"&F18 -> 20/3 | I18: =IF(G18="","",VLOOKUP(H18,ورقة1!$A$1:$B$240,2,0)) -> 853 | J18: =F18 -> 3 | K18: =IF(G18="","",G18+1) -> 21 | L18: =K18&"/"&J18 -> 21/3 | M18: =IF(K18="","",VLOOKUP(L18,ورقة1!$A$1:$B$240,2,0)) -> 870 | N18: =Z18+(AA18*30)+(AB18*365) -> 0 | O18: =#REF!+(#REF!*30)+#REF!*365 -> #REF! | P18: 45932 | Q18: =IF(P18="","",P18+365) -> 46297 | R18: =IF(P18="","",EDATE(P18,12+AG18)+AC18-N18) -> 46297 | S18: =IF(P18="","",IF(T18=TRUE,"يستحق العلاوة",IF(V18=TRUE,"قريبا يستحق العلاوة"," "))) | T18: =AND(MONTH(U18)=MONTH(R18),YEAR(U18)=YEAR(R18)) -> FALSE | U18: =TODAY() -> 46035 | V18: =AND(R18-U18<30,U18<R18) -> FALSE | AG18: =(((AD18*3)+(AE18*6)+(AF18*12))-AH18) -> 0 | AH18: =W18+X18 -> 0 | AK18: ملاك قديم | AM18: scrypt:32768:8:1$E8bouBvuMTo7cMQ6$91a63a8c38a868943046dd27bfef0becf36b0e01a8e57d74115db3e6b125d4f0407a8de846195aa73ec18fb980d7a4d7877852728e35db1a9eeec3ba681b3ee6 | AN18: 1 | AO18: 1 | AP18: ذكر
A19: 18 | B19: 100264832 | C19: اجلال هوبي جبار ياسين العزاوي | D19: مدير حسابات | E19: بكالوريوس محاسبة | F19: 3 | G19: 5 | H19: =G19&"/"&F19 -> 5/3 | I19: =IF(G19="","",VLOOKUP(H19,ورقة1!$A$1:$B$240,2,0)) -> 640 | J19: =F19 -> 3 | K19: =IF(G19="","",G19+1) -> 6 | L19: =K19&"/"&J19 -> 6/3 | M19: =IF(K19="","",VLOOKUP(L19,ورقة1!$A$1:$B$240,2,0)) -> 650 | N19: =Z19+(AA19*30)+(AB19*365) -> 0 | O19: =#REF!+(#REF!*30)+#REF!*365 -> #REF! | P19: 45892 | Q19: =IF(P19="","",P19+365) -> 46257 | R19: =IF(P19="","",EDATE(P19,12+AG19)+AC19-N19) -> 46257 | S19: =IF(P19="","",IF(T19=TRUE,"يستحق العلاوة",IF(V19=TRUE,"قريبا يستحق العلاوة"," "))) | T19: =AND(MONTH(U19)=MONTH(R19),YEAR(U19)=YEAR(R19)) -> FALSE | U19: =TODAY() -> 46035 | V19: =AND(R19-U19<30,U19<R19) -> FALSE | AG19: =(((AD19*3)+(AE19*6)+(AF19*12))-AH19) -> 0 | AH19: =W19+X19 -> 0 | AK19: ملاك قديم | AM19: scrypt:32768:8:1$vRrvJkD5aJfEeiPj$f8e7bb81982b0aeb0e8591855b967740f195c3a1d8edfdd143d5ecdd256b46f45023be3fd535d336af423bc1091570b26d582c6ab08b99351501b553dae1e277 | AN19: 1 | AO19: 1 | AP19: انثى
A20: 19 | B20: 100269725 | C20: احمد قاسم محمد محمود القيسي | D20: رئيس مهندسين | E20: بكالوريوس هندسة كهرباء | F20: 3 | G20: 2 | H20: =G20&"/"&F20 -> 2/3 | I20: =IF(G20="","",VLOOKUP(H20,ورقة1!$A$1:$B$240,2,0)) -> 610 | J20: =F20 -> 3 | K20: =IF(G20="","",G20+1) -> 3 | L20: =K20&"/"&J20 -> 3/3 | M20: =IF(K20="","",VLOOKUP(L20,ورقة1!$A$1:$B$240,2,0)) -> 620 | N20: =Z20+(AA20*30)+(AB20*365) -> 0 | O20: =#REF!+(#REF!*30)+#REF!*365 -> #REF! | P20: 45935 | Q20: =IF(P20="","",P20+365) -> 46300 | R20: =IF(P20="","",EDATE(P20,12+AG20)+AC20-N20) -> 46208 | S20: =IF(P20="","",IF(T20=TRUE,"يستحق العلاوة",IF(V20=TRUE,"قريبا يستحق العلاوة"," "))) | T20: =AND(MONTH(U20)=MONTH(R20),YEAR(U20)=YEAR(R20)) -> FALSE | U20: =TODAY() -> 46035 | V20: =AND(R20-U20<30,U20<R20) -> FALSE | X20: 3 | Y20: 51990في 1/10/2025 57495في 23/10/2025 60534في 4/11/2025 | AG20: =(((AD20*3)+(AE20*6)+(AF20*12))-AH20) -> -3 | AH20: =W20+X20 -> 3 | AK20: ملاك قديم | AL20: تم الترقية 2025 | AM20: scrypt:32768:8:1$4lQ1zAi7deCxUiNz$4b65f168f91d25697ce58b56d5e664d7db3e829fe1d2217e10235fd266ce03a82971b6e8691cfc953accdb48e8a820292719d9762dae82c00b7dbf9ce45b498d | AN20: 1 | AO20: 1 | AP20: ذكر
A21: 20 | B21: 100269684 | C21: احمد محمود احمد حمادي الدليمي | D21: مدير فني | E21: اعدادية كهرباء | F21: 3 | G21: 13 | H21: =G21&"/"&F21 -> 13/3 | I21: =IF(G21="","",VLOOKUP(H21,ورقة1!$A$1:$B$240,2,0)) -> 734 | J21: =F21 -> 3 | K21: =IF(G21="","",G21+1) -> 14 | L21: =K21&"/"&J21 -> 14/3 | M21: =IF(K21="","",VLOOKUP(L21,ورقة1!$A$1:$B$240,2,0)) -> 751 | N21: =Z21+(AA21*30)+(AB21*365) -> 0 | O21: =#REF!+(#REF!*30)+#REF!*365 -> #REF! | P21: 45932 | Q21: =IF(P21="","",P21+365) -> 46297 | R21: =IF(P21="","",EDATE(P21,12+AG21)+AC21-N21) -> 46297 | S21: =IF(P21="","",IF(T21=TRUE,"يستحق العلاوة",IF(V21=TRUE,"قريبا يستحق العلاوة"," "))) | T21: =AND(MONTH(U21)=MONTH(R21),YEAR(U21)=YEAR(R21)) -> FALSE | U21: =TODAY() -> 46035 | V21: =AND(R21-U21<30,U21<R21) -> FALSE | AG21: =(((AD21*3)+(AE21*6)+(AF21*12))-AH21) -> 0 | AH21: =W21+X21 -> 0 | AK21: ملاك قديم | AM21: scrypt:32768:8:1$OlWMXUSoUJW9lJmd$2de99bb45f9ee02e8c80e3c6bf1777153e6a7d4fb14694c06d4cd0bdd28fadc378ebd4db5b59abbafce67a7770efe95c63bf1c0187069a42400d72aca60560ae | AN21: 1 | AO21: 1 | AP21: ذكر
A22: 21 | B22: 148862164 | C22: اسراء علي حسين ظاهر الجبوري | D22: مدير حسابات | E22: بكالوريوس محاسبة | F22: 3 | G22: 2 | H22: =G22&"/"&F22 -> 2/3 | I22: =IF(G22="","",VLOOKUP(H22,ورقة1!$A$1:$B$240,2,0)) -> 610 | J22: =F22 -> 3 | K22: =IF(G22="","",G22+1) -> 3 | L22: =K22&"/"&J22 -> 3/3 | M22: =IF(K22="","",VLOOKUP(L22,ورقة1!$A$1:$B$240,2,0)) -> 620 | N22: =Z22+(AA22*30)+(AB22*365) -> 0 | O22: =#REF!+(#REF!*30)+#REF!*365 -> #REF! | P22: 45685 | Q22: =IF(P22="","",P22+365) -> 46050 | R22: =IF(P22="","",EDATE(P22,12+AG22)+AC22-N22) -> 46050 | S22: =IF(P22="","",IF(T22=TRUE,"يستحق العلاوة",IF(V22=TRUE,"قريبا يستحق العلاوة"," "))) -> يستحق العلاوة | T22: =AND(MONTH(U22)=MONTH(R22),YEAR(U22)=YEAR(R22)) -> TRUE | U22: =TODAY() -> 46035 | V22: =AND(R22-U22<30,U22<R22) -> TRUE | AG22: =(((AD22*3)+(AE22*6)+(AF22*12))-AH22) -> 0 | AH22: =W22+X22 -> 0 | AK22: ملاك قديم | AL22: تم الترقية 2025 | AM22: scrypt:32768:8:1$JbUTqYMxy4aAHj5i$8e1057982ca928d05a31dcf1876a29e536a1fb3429c22388bbac4fcffd14c9adaf0beea375a690c33607d9663574d457b234d8886e1fac31e2c4035f28975722 | AN22: 1 | AO22: 1 | AP22: انثى
A23: 22 | B23: 100269712 | C23: اميمة محسن عبد نصار الجنابي | D23: رئيس مهندسين | E23: بكالوريوس هندسة | F23: 3 | G23: 3 | H23: =G23&"/"&F23 -> 3/3 | I23: =IF(G23="","",VLOOKUP(H23,ورقة1!$A$1:$B$240,2,0)) -> 620 | J23: =F23 -> 3 | K23: =IF(G23="","",G23+1) -> 4 | L23: =K23&"/"&J23 -> 4/3 | M23: =IF(K23="","",VLOOKUP(L23,ورقة1!$A$1:$B$240,2,0)) -> 630 | N23: =Z23+(AA23*30)+(AB23*365) -> 0 | O23: =#REF!+(#REF!*30)+#REF!*365 -> #REF! | P23: 45997 | Q23: =IF(P23="","",P23+365) -> 46362 | R23: =IF(P23="","",EDATE(P23,12+AG23)+AC23-N23) -> 46362 | S23: =IF(P23="","",IF(T23=TRUE,"يستحق العلاوة",IF(V23=TRUE,"قريبا يستحق العلاوة"," "))) | T23: =AND(MONTH(U23)=MONTH(R23),YEAR(U23)=YEAR(R23)) -> FALSE | U23: =TODAY() -> 46035 | V23: =AND(R23-U23<30,U23<R23) -> FALSE | AG23: =(((AD23*3)+(AE23*6)+(AF23*12))-AH23) -> 0 | AH23: =W23+X23 -> 0 | AK23: ملاك قديم | AL23: تم الترقية 2025 | AM23: scrypt:32768:8:1$ERaaG3priCEV7yeY$42d51d60da970e153d9811d2bbf418d6dcc6fc53538c90eca31f4b4fbcc2719d8b8a8a3735a6862d4bf6ae84f76a1ccdb0d9c82238899696141e19228313dcd3 | AN23: 1 | AO23: 1 | AP23: انثى
A24: 23 | B24: 148927520 | C24: اوراد عماد صبري جبار | D24: رئيس مهندسين | E24: بكالوريوس هندسة ميكانيك | F24: 3 | G24: 2 | H24: =G24&"/"&F24 -> 2/3 | I24: =IF(G24="","",VLOOKUP(H24,ورقة1!$A$1:$B$240,2,0)) -> 610 | J24: =F24 -> 3 | K24: =IF(G24="","",G24+1) -> 3 | L24: =K24&"/"&J24 -> 3/3 | M24: =IF(K24="","",VLOOKUP(L24,ورقة1!$A$1:$B$240,2,0)) -> 620 | N24: =Z24+(AA24*30)+(AB24*365) -> 0 | O24: =#REF!+(#REF!*30)+#REF!*365 -> #REF! | P24: 45952 | Q24: =IF(P24="","",P24+365) -> 46317 | R24: =IF(P24="","",EDATE(P24,12+AG24)+AC24-N24) -> 46317 | S24: =IF(P24="","",IF(T24=TRUE,"يستحق العلاوة",IF(V24=TRUE,"قريبا يستحق العلاوة"," "))) | T24: =AND(MONTH(U24)=MONTH(R24),YEAR(U24)=YEAR(R24)) -> FALSE | U24: =TODAY() -> 46035 | V24: =AND(R24-U24<30,U24<R24) -> FALSE | AG24: =(((AD24*3)+(AE24*6)+(AF24*12))-AH24) -> 0 | AH24: =W24+X24 -> 0 | AK24: ملاك قديم | AL24: تم الترقية2025 | AM24: scrypt:32768:8:1$7XSWpRyGCuT90T62$60725f030f4a402d649594e52e817b890bd82b60fd491a350181ca09a03e3afcc48f1e8e3d52a90ec9cf363d37bedc939043c2e14fcec28f1496b58e6a61fd91 | AN24: 1 | AO24: 1 | AP24: انثى
A25: 24 | B25: 148824726 | C25: اوس محسن عبد نصار الجنابي | D25: رئيس مهندسين | E25: ماجستير عبوم هندسة مواد | F25: 3 | G25: 1 | H25: =G25&"/"&F25 -> 1/3 | I25: =IF(G25="","",VLOOKUP(H25,ورقة1!$A$1:$B$240,2,0)) -> 600 | J25: =F25 -> 3 | K25: =IF(G25="","",G25+1) -> 2 | L25: =K25&"/"&J25 -> 2/3 | M25: =IF(K25="","",VLOOKUP(L25,ورقة1!$A$1:$B$240,2,0)) -> 610 | N25: =Z25+(AA25*30)+(AB25*365) -> 0 | O25: =#REF!+(#REF!*30)+#REF!*365 -> #REF! | P25: 46006 | Q25: =IF(P25="","",P25+365) -> 46371 | R25: =IF(P25="","",EDATE(P25,12+AG25)+AC25-N25) -> 46371 | S25: =IF(P25="","",IF(T25=TRUE,"يستحق العلاوة",IF(V25=TRUE,"قريبا يستحق العلاوة"," "))) | T25: =AND(MONTH(U25)=MONTH(R25),YEAR(U25)=YEAR(R25)) -> FALSE | U25: =TODAY() -> 46035 | V25: =AND(R25-U25<30,U25<R25) -> FALSE | AG25: =(((AD25*3)+(AE25*6)+(AF25*12))-AH25) -> 0 | AH25: =W25+X25 -> 0 | AK25: ملاك قديم | AL25: تم الترقية 2025 | AM25: scrypt:32768:8:1$sscTeaWyu4qtgxxe$a461e630e77c781bc0151a1af4719316506cce602d7b90dc935d1336b1757f66e023f6ea1bb26eb2f8e4caac29a8b571c8e542fc90e0d5324d2ffbf2b0515051 | AN25: 1 | AO25: 1 | AP25: ذكر
A26: 25 | B26: 100268508 | C26: ثائر حسن عيدان غيلان الربيعي | D26: مدير فني | E26: اعدادية سيارات | F26: 3 | G26: 20 | H26: =G26&"/"&F26 -> 20/3 | I26: =IF(G26="","",VLOOKUP(H26,ورقة1!$A$1:$B$240,2,0)) -> 853 | J26: =F26 -> 3 | K26: =IF(G26="","",G26+1) -> 21 | L26: =K26&"/"&J26 -> 21/3 | M26: =IF(K26="","",VLOOKUP(L26,ورقة1!$A$1:$B$240,2,0)) -> 870 | N26: =Z26+(AA26*30)+(AB26*365) -> 0 | O26: =#REF!+(#REF!*30)+#REF!*365 -> #REF! | P26: 45932 | Q26: =IF(P26="","",P26+365) -> 46297 | R26: =IF(P26="","",EDATE(P26,12+AG26)+AC26-N26) -> 46297 | S26: =IF(P26="","",IF(T26=TRUE,"يستحق العلاوة",IF(V26=TRUE,"قريبا يستحق العلاوة"," "))) | T26: =AND(MONTH(U26)=MONTH(R26),YEAR(U26)=YEAR(R26)) -> FALSE | U26: =TODAY() -> 46035 | V26: =AND(R26-U26<30,U26<R26) -> FALSE | AG26: =(((AD26*3)+(AE26*6)+(AF26*12))-AH26) -> 0 | AH26: =W26+X26 -> 0 | AK26: ملاك قديم | AM26: scrypt:32768:8:1$DEGWBVGQF9ys0VLr$4c0673ad384e8c2924b104a17f187485b12f5e04c311b371cd2617333e2e30eb1f9d71a3e6af7525c5c157fa42b03f585d52e27d8a4daeaea7abb42fee780003 | AN26: 1 | AO26: 1 | AP26: ذكر
A27: 26 | B27: 148824979 | C27: حيدر عبدالحسين كريم بريسم | D27: مشاور قانوني اقدم | E27: ماجستير قانون خاص | F27: 3 | G27: 1 | H27: =G27&"/"&F27 -> 1/3 | I27: =IF(G27="","",VLOOKUP(H27,ورقة1!$A$1:$B$240,2,0)) -> 600 | J27: =F27 -> 3 | K27: =IF(G27="","",G27+1) -> 2 | L27: =K27&"/"&J27 -> 2/3 | M27: =IF(K27="","",VLOOKUP(L27,ورقة1!$A$1:$B$240,2,0)) -> 610 | N27: =Z27+(AA27*30)+(AB27*365) -> 0 | O27: =#REF!+(#REF!*30)+#REF!*365 -> #REF! | P27: 45933 | Q27: =IF(P27="","",P27+365) -> 46298 | R27: =IF(P27="","",EDATE(P27,12+AG27)+AC27-N27) -> 46268 | S27: =IF(P27="","",IF(T27=TRUE,"يستحق العلاوة",IF(V27=TRUE,"قريبا يستحق العلاوة"," "))) | T27: =AND(MONTH(U27)=MONTH(R27),YEAR(U27)=YEAR(R27)) -> FALSE | U27: =TODAY() -> 46035 | V27: =AND(R27-U27<30,U27<R27) -> FALSE | X27: 1 | Y27: 61879في 10/11/2025 | AG27: =(((AD27*3)+(AE27*6)+(AF27*12))-AH27) -> -1 | AH27: =W27+X27 -> 1 | AK27: ملاك قديم | AL27: تم الترقية 2025 | AM27: scrypt:32768:8:1$xHAf0QMp2IJp83G7$6c7de435595be7ee2cb9ab2a678c3d307cb83b9fdeaf34c9cb4c507f859e7a2e906a1febe795191be5e1cf51487915a9ec24207007558419ca04b85b9e186972 | AN27: 1 | AO27: 1 | AP27: ذكر
A28: 27 | B28: 100249644 | C28: خالد حسن لازم عيسى الفريجي | D28: مشاور قانوني اقدم | E28: ماجستير قانون | F28: 3 | G28: 4 | H28: =G28&"/"&F28 -> 4/3 | I28: =IF(G28="","",VLOOKUP(H28,ورقة1!$A$1:$B$240,2,0)) -> 630 | J28: =F28 -> 3 | K28: =IF(G28="","",G28+1) -> 5 | L28: =K28&"/"&J28 -> 5/3 | M28: =IF(K28="","",VLOOKUP(L28,ورقة1!$A$1:$B$240,2,0)) -> 640 | N28: =Z28+(AA28*30)+(AB28*365) -> 0 | O28: =#REF!+(#REF!*30)+#REF!*365 -> #REF! | P28: 45998 | Q28: =IF(P28="","",P28+365) -> 46363 | R28: =IF(P28="","",EDATE(P28,12+AG28)+AC28-N28) -> 46363 | S28: =IF(P28="","",IF(T28=TRUE,"يستحق العلاوة",IF(V28=TRUE,"قريبا يستحق العلاوة"," "))) | T28: =AND(MONTH(U28)=MONTH(R28),YEAR(U28)=YEAR(R28)) -> FALSE | U28: =TODAY() -> 46035 | V28: =AND(R28-U28<30,U28<R28) -> FALSE | AG28: =(((AD28*3)+(AE28*6)+(AF28*12))-AH28) -> 0 | AH28: =W28+X28 -> 0 | AK28: ملاك قديم | AM28: scrypt:32768:8:1$gPt5CdM0cYHrLJpB$0e173f4cc2b1c871e268b7c63e53d26bc5802e45df4eecf82aff643fc94a1906103f714522c23a0d396a2fab852f5f2ceebd1bf6d5753a304e2d9c97c923937d | AN28: 1 | AO28: 1 | AP28: ذكر
A29: 28 | B29: 100268537 | C29: خالد سالم حمدي حسن الحيالي | D29: مدير فني | E29: اعدادية صناعة تشغيل وحدات | F29: 3 | G29: 6 | H29: =G29&"/"&F29 -> 6/3 | I29: =IF(G29="","",VLOOKUP(H29,ورقة1!$A$1:$B$240,2,0)) -> 650 | J29: =F29 -> 3 | K29: =IF(G29="","",G29+1) -> 7 | L29: =K29&"/"&J29 -> 7/3 | M29: =IF(K29="","",VLOOKUP(L29,ورقة1!$A$1:$B$240,2,0)) -> 660 | N29: =Z29+(AA29*30)+(AB29*365) -> 0 | O29: =#REF!+(#REF!*30)+#REF!*365 -> #REF! | P29: 45932 | Q29: =IF(P29="","",P29+365) -> 46297 | R29: =IF(P29="","",EDATE(P29,12+AG29)+AC29-N29) -> 46297 | S29: =IF(P29="","",IF(T29=TRUE,"يستحق العلاوة",IF(V29=TRUE,"قريبا يستحق العلاوة"," "))) | T29: =AND(MONTH(U29)=MONTH(R29),YEAR(U29)=YEAR(R29)) -> FALSE | U29: =TODAY() -> 46035 | V29: =AND(R29-U29<30,U29<R29) -> FALSE | AG29: =(((AD29*3)+(AE29*6)+(AF29*12))-AH29) -> 0 | AH29: =W29+X29 -> 0 | AK29: ملاك قديم | AM29: scrypt:32768:8:1$9XKMm6UuKSTJXDLw$fd64c58d143006811dfb2a46195032152c967f0e6386f867b5cc9df60670c67a9a0ce756b7a32fa70c550b557fc395900050044cc8f2e122ec0eb7e095e1be56 | AN29: 1 | AO29: 1 | AP29: ذكر
A30: 29 | B30: 100270701 | C30: دينا طارق سعيد شريف الصواف | D30: رئيس مهندسين | E30: بكالوريوس علوم في الهندسة الميكانيكية | F30: 3 | G30: 3 | H30: =G30&"/"&F30 -> 3/3 | I30: =IF(G30="","",VLOOKUP(H30,ورقة1!$A$1:$B$240,2,0)) -> 620 | J30: =F30 -> 3 | K30: =IF(G30="","",G30+1) -> 4 | L30: =K30&"/"&J30 -> 4/3 | M30: =IF(K30="","",VLOOKUP(L30,ورقة1!$A$1:$B$240,2,0)) -> 630 | N30: =Z30+(AA30*30)+(AB30*365) -> 0 | O30: =#REF!+(#REF!*30)+#REF!*365 -> #REF! | P30: 45881 | Q30: =IF(P30="","",P30+365) -> 46246 | R30: =IF(P30="","",EDATE(P30,12+AG30)+AC30-N30) -> 46246 | S30: =IF(P30="","",IF(T30=TRUE,"يستحق العلاوة",IF(V30=TRUE,"قريبا يستحق العلاوة"," "))) | T30: =AND(MONTH(U30)=MONTH(R30),YEAR(U30)=YEAR(R30)) -> FALSE | U30: =TODAY() -> 46035 | V30: =AND(R30-U30<30,U30<R30) -> FALSE | AG30: =(((AD30*3)+(AE30*6)+(AF30*12))-AH30) -> 0 | AH30: =W30+X30 -> 0 | AK30: ملاك قديم | AL30: تم الترقية | AM30: scrypt:32768:8:1$1VmH70aNiRFx9B9I$311da3ab6c7e889899881d0f105cbcec6312096408f217ff2782407d8e134dc3c89b9fab723988109140497e0ec413d3a0e01490d2a1bc8b08feaa6a1c7fdc8e | AN30: 1 | AO30: 1 | AP30: انثى
A31: 30 | B31: 100270871 | C31: رعد مديح جميل محمد النعيمي | D31: مدير فني | E31: اعدادية كهرباء | F31: 3 | G31: 9 | H31: =G31&"/"&F31 -> 9/3 | I31: =IF(G31="","",VLOOKUP(H31,ورقة1!$A$1:$B$240,2,0)) -> 680 | J31: =F31 -> 3 | K31: =IF(G31="","",G31+1) -> 10 | L31: =K31&"/"&J31 -> 10/3 | M31: =IF(K31="","",VLOOKUP(L31,ورقة1!$A$1:$B$240,2,0)) -> 690 | N31: =Z31+(AA31*30)+(AB31*365) -> 0 | O31: =#REF!+(#REF!*30)+#REF!*365 -> #REF! | P31: 45932 | Q31: =IF(P31="","",P31+365) -> 46297 | R31: =IF(P31="","",EDATE(P31,12+AG31)+AC31-N31) -> 46297 | S31: =IF(P31="","",IF(T31=TRUE,"يستحق العلاوة",IF(V31=TRUE,"قريبا يستحق العلاوة"," "))) | T31: =AND(MONTH(U31)=MONTH(R31),YEAR(U31)=YEAR(R31)) -> FALSE | U31: =TODAY() -> 46035 | V31: =AND(R31-U31<30,U31<R31) -> FALSE | AG31: =(((AD31*3)+(AE31*6)+(AF31*12))-AH31) -> 0 | AH31: =W31+X31 -> 0 | AK31: ملاك قديم | AL31: تم الترقية | AM31: scrypt:32768:8:1$DjP9T3c2Sl3iTPoN$7d4f42dc7cfd2f2d925ec5f3a4b3a74caaaa9c6061069ecceca982d5b6d8fadc096ec7eab8144503bafadd231f39783264fcc5a14c1113a68d2be535ddb69103 | AN31: 1 | AO31: 1 | AP31: ذكر
A32: 31 | B32: 100256628 | C32: زهراء خالد عثمان ناجي | D32: مدير | E32: بكالوريوس اعلام | F32: 3 | G32: 5 | H32: =G32&"/"&F32 -> 5/3 | I32: =IF(G32="","",VLOOKUP(H32,ورقة1!$A$1:$B$240,2,0)) -> 640 | J32: =F32 -> 3 | K32: =IF(G32="","",G32+1) -> 6 | L32: =K32&"/"&J32 -> 6/3 | M32: =IF(K32="","",VLOOKUP(L32,ورقة1!$A$1:$B$240,2,0)) -> 650 | N32: =Z32+(AA32*30)+(AB32*365) -> 0 | O32: =#REF!+(#REF!*30)+#REF!*365 -> #REF! | P32: 45991 | Q32: =IF(P32="","",P32+365) -> 46356 | R32: =IF(P32="","",EDATE(P32,12+AG32)+AC32-N32) -> 46356 | S32: =IF(P32="","",IF(T32=TRUE,"يستحق العلاوة",IF(V32=TRUE,"قريبا يستحق العلاوة"," "))) | T32: =AND(MONTH(U32)=MONTH(R32),YEAR(U32)=YEAR(R32)) -> FALSE | U32: =TODAY() -> 46035 | V32: =AND(R32-U32<30,U32<R32) -> FALSE | AG32: =(((AD32*3)+(AE32*6)+(AF32*12))-AH32) -> 0 | AH32: =W32+X32 -> 0 | AK32: ملاك قديم | AM32: scrypt:32768:8:1$jhtzC9R3kppjxU0f$9a90b6baccd20e2d071dc7bf14088d8301cb01b6a0bcc5f05a16250a1a74f8da2c322fbe4bd5e550f87a5aff9fb07746bdbc288e7831de1437861c0af19f5ea9 | AN32: 1 | AO32: 1 | AP32: انثى
A33: 32 | B33: 100269303 | C33: سيف باسم محمد احمد الطائي | D33: رئيس مهندسين | E33: بكالوريوس هندسة كهرباء | F33: 3 | G33: 3 | H33: =G33&"/"&F33 -> 3/3 | I33: =IF(G33="","",VLOOKUP(H33,ورقة1!$A$1:$B$240,2,0)) -> 620 | J33: =F33 -> 3 | K33: =IF(G33="","",G33+1) -> 4 | L33: =K33&"/"&J33 -> 4/3 | M33: =IF(K33="","",VLOOKUP(L33,ورقة1!$A$1:$B$240,2,0)) -> 630 | N33: =Z33+(AA33*30)+(AB33*365) -> 0 | O33: =#REF!+(#REF!*30)+#REF!*365 -> #REF! | P33: 45954 | Q33: =IF(P33="","",P33+365) -> 46319 | R33: =IF(P33="","",EDATE(P33,12+AG33)+AC33-N33) -> 46289 | S33: =IF(P33="","",IF(T33=TRUE,"يستحق العلاوة",IF(V33=TRUE,"قريبا يستحق العلاوة"," "))) | T33: =AND(MONTH(U33)=MONTH(R33),YEAR(U33)=YEAR(R33)) -> FALSE | U33: =TODAY() -> 46035 | V33: =AND(R33-U33<30,U33<R33) -> FALSE | X33: 1 | Y33: 52711في 6/10/2025 | AG33: =(((AD33*3)+(AE33*6)+(AF33*12))-AH33) -> -1 | AH33: =W33+X33 -> 1 | AK33: ملاك قديم | AL33: تم الترقية 2025 | AM33: scrypt:32768:8:1$8renDmkkGgfFmbP1$53bfd946b21f935216c1593d9ff18ba714a9b876ee1444c9e03e87d3497f549aece03293e0ec0d8458efdd16ff22d9c83d74d43e61a7cd3380329f596acfbc1a | AN33: 1 | AO33: 1 | AP33: ذكر
A34: 33 | B34: 100268540 | C34: طلال كامل عبدالله حسين العزاوي | D34: مدير فني | E34: اعدادية ميكانيك | F34: 3 | G34: 12 | H34: =G34&"/"&F34 -> 12/3 | I34: =IF(G34="","",VLOOKUP(H34,ورقة1!$A$1:$B$240,2,0)) -> 717 | J34: =F34 -> 3 | K34: =IF(G34="","",G34+1) -> 13 | L34: =K34&"/"&J34 -> 13/3 | M34: =IF(K34="","",VLOOKUP(L34,ورقة1!$A$1:$B$240,2,0)) -> 734 | N34: =Z34+(AA34*30)+(AB34*365) -> 0 | O34: =#REF!+(#REF!*30)+#REF!*365 -> #REF! | P34: 45932 | Q34: =IF(P34="","",P34+365) -> 46297 | R34: =IF(P34="","",EDATE(P34,12+AG34)+AC34-N34) -> 46267 | S34: =IF(P34="","",IF(T34=TRUE,"يستحق العلاوة",IF(V34=TRUE,"قريبا يستحق العلاوة"," "))) | T34: =AND(MONTH(U34)=MONTH(R34),YEAR(U34)=YEAR(R34)) -> FALSE | U34: =TODAY() -> 46035 | V34: =AND(R34-U34<30,U34<R34) -> FALSE | X34: 1 | Y34: 53813في 8/10/2025 | AG34: =(((AD34*3)+(AE34*6)+(AF34*12))-AH34) -> -1 | AH34: =W34+X34 -> 1 | AK34: ملاك قديم | AM34: scrypt:32768:8:1$q1y3q3EJ9MXGPaec$bdae9525b9f87a1c3c0fa5d3c46560775282e94bd8b511706cf35ba1e843a65fa98c37b991b63cfc321b2f137f8f31f46be7e5733c4da0813b15694341adeb23 | AN34: 1 | AO34: 1 | AP34: ذكر
A35: 34 | B35: 100269811 | C35: عبدالرحيم حافظ نعيم عذاري الميالي | D35: مدير فني | E35: اعدادية تشغيل وحدات | F35: 3 | G35: 14 | H35: =G35&"/"&F35 -> 14/3 | I35: =IF(G35="","",VLOOKUP(H35,ورقة1!$A$1:$B$240,2,0)) -> 751 | J35: =F35 -> 3 | K35: =IF(G35="","",G35+1) -> 15 | L35: =K35&"/"&J35 -> 15/3 | M35: =IF(K35="","",VLOOKUP(L35,ورقة1!$A$1:$B$240,2,0)) -> 768 | N35: =Z35+(AA35*30)+(AB35*365) -> 0 | O35: =#REF!+(#REF!*30)+#REF!*365 -> #REF! | P35: 45932 | Q35: =IF(P35="","",P35+365) -> 46297 | R35: =IF(P35="","",EDATE(P35,12+AG35)+AC35-N35) -> 46297 | S35: =IF(P35="","",IF(T35=TRUE,"يستحق العلاوة",IF(V35=TRUE,"قريبا يستحق العلاوة"," "))) | T35: =AND(MONTH(U35)=MONTH(R35),YEAR(U35)=YEAR(R35)) -> FALSE | U35: =TODAY() -> 46035 | V35: =AND(R35-U35<30,U35<R35) -> FALSE | AG35: =(((AD35*3)+(AE35*6)+(AF35*12))-AH35) -> 0 | AH35: =W35+X35 -> 0 | AK35: ملاك قديم | AM35: scrypt:32768:8:1$Bsm4wsBlQ8VwAzJ4$15a4d42efdf960ca2875a7e58bfafe30c3cc5a5732e8799657adf7082ccc4c787b46a87bae87692993e97620b13e54b51b443eae498bbe7ae138988e799cf432 | AN35: 1 | AO35: 1 | AP35: ذكر
A36: 35 | B36: 148842645 | C36: عبداللطيف حسين علي عباس | D36: مدير فني | E36: اعدادية كهرباء | F36: 3 | G36: 1 | H36: =G36&"/"&F36 -> 1/3 | I36: =IF(G36="","",VLOOKUP(H36,ورقة1!$A$1:$B$240,2,0)) -> 600 | J36: =F36 -> 3 | K36: =IF(G36="","",G36+1) -> 2 | L36: =K36&"/"&J36 -> 2/3 | M36: =IF(K36="","",VLOOKUP(L36,ورقة1!$A$1:$B$240,2,0)) -> 610 | N36: =Z36+(AA36*30)+(AB36*365) -> 26 | O36: =#REF!+(#REF!*30)+#REF!*365 -> #REF! | P36: 45900 | Q36: =IF(P36="","",P36+365) -> 46265 | R36: =IF(P36="","",EDATE(P36,12+AG36)+AC36-N36) -> 46239 | S36: =IF(P36="","",IF(T36=TRUE,"يستحق العلاوة",IF(V36=TRUE,"قريبا يستحق العلاوة"," "))) | T36: =AND(MONTH(U36)=MONTH(R36),YEAR(U36)=YEAR(R36)) -> FALSE | U36: =TODAY() -> 46035 | V36: =AND(R36-U36<30,U36<R36) -> FALSE | Z36: 26 | AG36: =(((AD36*3)+(AE36*6)+(AF36*12))-AH36) -> 0 | AH36: =W36+X36 -> 0 | AK36: ملاك قديم | AL36: تم الترقية 2025 | AM36: scrypt:32768:8:1$o9G7vJEFHhdBk858$f0b819b34c6d0d22deff067b99ff516f116b64e627236ee8d71c86e977255ec4d1ef3ebd3d1e3b14ad71c309042e62199b7b7a7db7078c83c363e145114ca332 | AN36: 1 | AO36: 1 | AP36: ذكر
A37: 36 | B37: 100253616 | C37: عدي عادل عبد علي | D37: مدير فني | E37: اعدادية صناعة سيارات | F37: 3 | G37: 2 | H37: =G37&"/"&F37 -> 2/3 | I37: =IF(G37="","",VLOOKUP(H37,ورقة1!$A$1:$B$240,2,0)) -> 610 | J37: =F37 -> 3 | K37: =IF(G37="","",G37+1) -> 3 | L37: =K37&"/"&J37 -> 3/3 | M37: =IF(K37="","",VLOOKUP(L37,ورقة1!$A$1:$B$240,2,0)) -> 620 | N37: =Z37+(AA37*30)+(AB37*365) -> 0 | O37: =#REF!+(#REF!*30)+#REF!*365 -> #REF! | P37: 45895 | Q37: =IF(P37="","",P37+365) -> 46260 | R37: =IF(P37="","",EDATE(P37,12+AG37)+AC37-N37) -> 46260 | S37: =IF(P37="","",IF(T37=TRUE,"يستحق العلاوة",IF(V37=TRUE,"قريبا يستحق العلاوة"," "))) | T37: =AND(MONTH(U37)=MONTH(R37),YEAR(U37)=YEAR(R37)) -> FALSE | U37: =TODAY() -> 46035 | V37: =AND(R37-U37<30,U37<R37) -> FALSE | AG37: =(((AD37*3)+(AE37*6)+(AF37*12))-AH37) -> 0 | AH37: =W37+X37 -> 0 | AM37: scrypt:32768:8:1$c7mNH5AAGKwaosFH$2e2a11322e5f01d731f563bff24ff258e14a8a8e054897a3b7d56a68afa17780f3fd05e29424ff7784d24e6a60430cab69bd583761fb45d1d9c18983d036830b | AN37: 1 | AO37: 1 | AP37: ذكر
A38: 37 | B38: 100243969 | C38: فاضل محمود عباس سلمان الدوري | D38: مدير فني | E38: اعدادية ميكانيك | F38: 3 | G38: 19 | H38: =G38&"/"&F38 -> 19/3 | I38: =IF(G38="","",VLOOKUP(H38,ورقة1!$A$1:$B$240,2,0)) -> 836 | J38: =F38 -> 3 | K38: =IF(G38="","",G38+1) -> 20 | L38: =K38&"/"&J38 -> 20/3 | M38: =IF(K38="","",VLOOKUP(L38,ورقة1!$A$1:$B$240,2,0)) -> 853 | N38: =Z38+(AA38*30)+(AB38*365) -> 0 | O38: =#REF!+(#REF!*30)+#REF!*365 -> #REF! | P38: 45932 | Q38: =IF(P38="","",P38+365) -> 46297 | R38: =IF(P38="","",EDATE(P38,12+AG38)+AC38-N38) -> 46297 | S38: =IF(P38="","",IF(T38=TRUE,"يستحق العلاوة",IF(V38=TRUE,"قريبا يستحق العلاوة"," "))) | T38: =AND(MONTH(U38)=MONTH(R38),YEAR(U38)=YEAR(R38)) -> FALSE | U38: =TODAY() -> 46035 | V38: =AND(R38-U38<30,U38<R38) -> FALSE | AG38: =(((AD38*3)+(AE38*6)+(AF38*12))-AH38) -> 0 | AH38: =W38+X38 -> 0 | AK38: ملاك قديم | AM38: scrypt:32768:8:1$n24ENFhrJ9MgNfgo$5f78487963a55ec1085b8dcbc545833113217e6913b58af707227ee27e4384704290947af99025100ce36646d54ef0c008426d0e9982191e24de47ff3d6a36e7 | AN38: 1 | AO38: 1 | AP38: ذكر
A39: 38 | B39: 100553321 | C39: فرات سلمان جاسم محمد البياتي | D39: رئيس مهندسين | E39: بكالوريوس هندسة ميكانيك | F39: 3 | G39: 5 | H39: =G39&"/"&F39 -> 5/3 | I39: =IF(G39="","",VLOOKUP(H39,ورقة1!$A$1:$B$240,2,0)) -> 640 | J39: =F39 -> 3 | K39: =IF(G39="","",G39+1) -> 6 | L39: =K39&"/"&J39 -> 6/3 | M39: =IF(K39="","",VLOOKUP(L39,ورقة1!$A$1:$B$240,2,0)) -> 650 | N39: =Z39+(AA39*30)+(AB39*365) -> 0 | O39: =#REF!+(#REF!*30)+#REF!*365 -> #REF! | P39: 45955 | Q39: =IF(P39="","",P39+365) -> 46320 | R39: =IF(P39="","",EDATE(P39,12+AG39)+AC39-N39) -> 46259 | S39: =IF(P39="","",IF(T39=TRUE,"يستحق العلاوة",IF(V39=TRUE,"قريبا يستحق العلاوة"," "))) | T39: =AND(MONTH(U39)=MONTH(R39),YEAR(U39)=YEAR(R39)) -> FALSE | U39: =TODAY() -> 46035 | V39: =AND(R39-U39<30,U39<R39) -> FALSE | X39: 2 | Y39: 60990في 5/11/2025 74314 في 31/12/2025 | AG39: =(((AD39*3)+(AE39*6)+(AF39*12))-AH39) -> -2 | AH39: =W39+X39 -> 2 | AK39: ملاك قديم | AL39: 4912 في 27/1/2025 9103في13/2/2025 14442في 13/3/2025 10986في 24/2025 11781 في 27/2/2025 10986في 24/2/2025 18526في 14/4/2025 قدم 6 اشهر 17745في 9/4/2025 20916في 24/4/2025 21547في 28/4/2025 26795في 28/5/2025 54636في 12/10/2025 60990في 5/11/2025 | AM39: scrypt:32768:8:1$V0uU7Fb3nyMLNuiF$788be432d4e0f4abe6942992cf52957a7e1ce993884a852bd2ac8ff8a12ec113927cfc90b9129c28415b00eb62baa1ee1b88daa00da9945918ba8e903a1a3771 | AN39: 1 | AO39: 1 | AP39: ذكر
A40: 39 | B40: 100277179 | C40: فرهان مزاحم ياسين عبود الغريري | D40: مدير | E40: بكالوريوس علوم عسكرية | F40: 3 | G40: 5 | H40: =G40&"/"&F40 -> 5/3 | I40: =IF(G40="","",VLOOKUP(H40,ورقة1!$A$1:$B$240,2,0)) -> 640 | J40: =F40 -> 3 | K40: =IF(G40="","",G40+1) -> 6 | L40: =K40&"/"&J40 -> 6/3 | M40: =IF(K40="","",VLOOKUP(L40,ورقة1!$A$1:$B$240,2,0)) -> 650 | N40: =Z40+(AA40*30)+(AB40*365) -> 0 | O40: =#REF!+(#REF!*30)+#REF!*365 -> #REF! | P40: 45821 | Q40: =IF(P40="","",P40+365) -> 46186 | R40: =IF(P40="","",EDATE(P40,12+AG40)+AC40-N40) -> 46155 | S40: =IF(P40="","",IF(T40=TRUE,"يستحق العلاوة",IF(V40=TRUE,"قريبا يستحق العلاوة"," "))) | T40: =AND(MONTH(U40)=MONTH(R40),YEAR(U40)=YEAR(R40)) -> FALSE | U40: =TODAY() -> 46035 | V40: =AND(R40-U40<30,U40<R40) -> FALSE | X40: 1 | Y40: 53813في 8/10/2025 | AG40: =(((AD40*3)+(AE40*6)+(AF40*12))-AH40) -> -1 | AH40: =W40+X40 -> 1 | AK40: ملاك قديم | AM40: scrypt:32768:8:1$AkmoUDrvc9JXhtCl$08571393a4be742b9b13f1803b848d2bf0dbaf670f0ee30392533469ffa25875cb05bb4ee0b8a7e7800b3f428722e9036e4a2acefe9b0419084f257b2fa78020 | AN40: 1 | AO40: 1 | AP40: ذكر
...

Sheet ورقة1
A1: 1/1 | B1: 910
A2: 2/1 | B2: 930
A3: 3/1 | B3: 950
A4: 4/1 | B4: 970
A5: 5/1 | B5: 990
A6: 6/1 | B6: 1010
A7: 7/1 | B7: 1030
A8: 8/1 | B8: 1050
A9: 9/1 | B9: 1070
A10: 10/1 | B10: 1090
A11: 11/1 | B11: 1110
A12: 1/2 | B12: 723
... A111: 12/1 | B111: 1130
A112: 13/1 | B112: =B111+20 -> 1150
A113: 14/1 | B113: 1170
A114: 15/1 | B114: 1190
A115: 16/1 | B115: 1210
A116: 17/1 | B116: 1230
A117: 18/1 | B117: 1250
A118: 19/1 | B118: 1270
A119: 20/1 | B119: 1290
A120: 12/2 | B120: 913
A121: 13/2 | B121: 933
A122: 14/2 | B122: 953
A123: 15/2 | B123: 973
A124: 16/2 | B124: 993
... A240: 30/5 | B240: 603

Sheet علاوات عام ملاك جديد2024
A1: جدول مستحقي العلاوات لشهر اذار الملاك الجديد محطة كهرباء الشهيد علي سبع
A2: ت | B2: الاسم الثلاثي | C2: العنوان الوظيفي | D2: الدرجة | E2: المرحلة القديمة | F2: الراتب القديم | G2: المرحلة الجديدة | H2: الراتب الجديد | I2: تاريخ الاستحقاق القديم | J2: تاريخ الاستحقاق الجديد | K2: كتب الشكر | L2: رقم وتاريخ كتب الشكر | M2: خدمة المدورة | P2: اجازة بدون راتب / غيابات | Q2: لفت نظر / امومة | R2: انذار | S2: توبيخ | T2: رقم وتاريخ العقوبات | U2: الملاحضات
A3: 1 | B3: تغريد محمد عباس داود العبيدي | C3: معاون كيمياوي | D3: 7 | E3: 1 | F3: 296 | G3: 2 | H3: 302 | I3: 44909 | J3: 45336 | K3: 1 | L3: 17929 في 11/3/2024 | Q3: 1 | U3: امومة
A4: 2 | B4: رفل مصطفى حمد مصطفى التكريتي | C4: معاون مهندس | D4: 7 | E4: 1 | F4: 296 | G4: 2 | H4: 302 | I4: 44909 | J4: 45336 | K4: 1 | L4: 17929 في 11/3/2024 | Q4: 1 | U4: امومة
A5: 3 | B5: زينة احمد عبد عبدالله الصميدعي | C5: معاون مبرمج | D5: 7 | E5: 1 | F5: 296 | G5: 2 | H5: 302 | I5: 44909 | J5: 45336 | K5: 1 | L5: 17929 في 11/3/2024 | Q5: 1 | U5: امومة
A6: 4 | B6: وديان جمال صعبان خضيرالعكيدي | C6: معاون ملاحظ | D6: 7 | E6: 1 | F6: 296 | G6: 2 | H6: 302 | I6: 44909 | J6: 45336 | K6: 1 | L6: 17929 في 11/3/2024 | Q6: 1 | U6: امومة
A7: 5 | B7: طيبة صباح ياسين عبدالكريم النجدي | C7: معاون مهندس | D7: 7 | E7: 1 | F7: 296 | G7: 2 | H7: 302 | I7: 44909 | J7: 45239 | K7: 2 | L7: 2237 12/4/2023 17929 في 11/3/2024 | P7: 26 | U7: 26 بدون راتب
A8: 6 | B8: صفا عبدالناصر عبدالفتاح عبد الراوي | C8: كاتب | D8: 8 | E8: 1 | F8: 260 | G8: 2 | H8: 263 | I8: 44909 | J8: 45336 | K8: 1 | L8: 17929 في 11/3/2024 | Q8: 1 | U8: امومة
A9: 7 | B9: طيبة خالد وليد هادي السامرائي | C9: كاتب | D9: 8 | E9: 1 | F9: 260 | G9: 2 | H9: 263 | I9: 44909 | J9: 45336 | K9: 1 | L9: 17929 في 11/3/2024 | Q9: 1 | U9: امومة
A10: 8 | B10: ادريس مجيد حميد جمعة اللهيبي | C10: حرفي اول | D10: 9 | E10: 1 | F10: 210 | G10: 2 | H10: 213 | I10: 44909 | J10: 45369 | K10: 1 | L10: 17929 في 11/3/2024 | P10: 125 | U10: 125 اربعة اشهر بدون راتب
A11: 9 | B11: ندى انور عبدالرحمن احمد | C11: حرفي اول | D11: 9 | E11: 1 | F11: 210 | G11: 2 | H11: 213 | I11: 44909 | J11: 45339 | K11: 2 | L11: 2237 12/4/2023 17929 في 11/3/2024 | P11: 34 | Q11: 1 | U11: 34+اجازة امومة
A12: 10 | B12: هبة يوسف كريم عبود سقي | C12: حرفي اول | D12: 9 | E12: 1 | F12: 210 | G12: 2 | H12: 213 | I12: 44909 | J12: 45331 | K12: 2 | L12: 2237 12/4/2023 17929 في 11/3/2024 | P12: 26 | Q12: 1 | U12: 26+اجازة امومة
A13: 11 | B13: محمد كريم امين ياس | C13: حرفي | D13: 10 | E13: 1 | F13: 170 | G13: 2 | H13: 173 | I13: 44909 | J13: 45365 | Q13: 1 | U13: عقوبة لفت نظر
A14: 12 | B14: مروان عبدالرحمن نوري عبدالعزيز | C14: حرفي | D14: 10 | E14: 4 | F14: 179 | G14: 5 | H14: 182 | I14: 44909 | J14: 45365 | Q14: 1 | U14: عقوبة لفت نظر
A15: 13 | B15: زمن مجيد هاشم ناصر الشميلاوي | C15: حرفي | D15: 10 | E15: 2 | F15: 173 | G15: 3 | H15: 176 | I15: 45063 | J15: 45399 | K15: 1 | L15: 17929 في 11/3/2024
A16: 14 | B16: زينب تركي حسن عبد التميمي | C16: حرفي | D16: 10 | E16: 2 | F16: 173 | G16: 3 | H16: 176 | I16: 45060 | J16: 45396 | K16: 1 | L16: 17929 في 11/3/2024
A17: 15 | B17: نور انور فخري فاضل الربيعي | C17: معاون ملاحظ | D17: 7 | E17: 1 | F17: 296 | G17: 2 | H17: 302 | I17: 45160 | J17: 45434 | K17: 3 | L17: 17929 في 11/3/2024 26994في 2024/4/21 26995في 2024/4/21
A18: 16 | B18: وفاء عباس مهدي عباس الغانمي | C18: معاون ملاحظ | D18: 7 | E18: 1 | F18: 296 | G18: 2 | H18: 302 | I18: 45153 | J18: 45427 | K18: 3 | L18: 24105 في 2024/4/7 17929 في 11/3/2024 27109 في 2024/4/22
A19: 17 | B19: رسل قحطان عدنان كريم | C19: معاون محاسب | D19: 7 | E19: 1 | F19: 296 | G19: 2 | H19: 302 | I19: 44909 | J19: 45183 | K19: 3 | L19: 2283 16/4/2023 2237 12/4/2023 17929 في 11/3/2024 | U19: تم تغيير العنوان
A20: 18 | B20: سارة قاسم طوفان شفيق الجبوري | C20: معاون محاسب | D20: 7 | E20: 1 | F20: 296 | G20: 2 | H20: 302 | I20: 44909 | J20: 45213 | K20: 2 | L20: 2237 12/4/2023 17929 في 11/3/2024 | U20: تم تغيير العنوان
A21: 19 | B21: شمس الضحى صفاء احمد محمد الفارس | C21: معاون محاسب | D21: 7 | E21: 1 | F21: 296 | G21: 2 | H21: 302 | I21: 44909 | J21: 45183 | K21: 3 | L21: 2283 16/4/2023 6240 3/9/2023 2237 12/4/2023 | U21: تم تغيير العنوان 17929 في 11/3/2024
A22: 20 | B22: عثمان خميس خلف كاظم الهيبي | C22: معاون مهندس تقني | D22: 7 | E22: 1 | F22: 296 | G22: 2 | H22: 302 | I22: 44909 | J22: 45244 | K22: 1 | L22: 17929 في 11/3/2024 | U22: تم تغيير العنوان
A23: 21 | B23: محمد احمد عواد صالح الفهداوي | C23: معاون محاسب | D23: 7 | E23: 1 | F23: 296 | G23: 2 | H23: 302 | I23: 44909 | J23: 45213 | K23: 2 | L23: 5977 24/8/2023 6240 3/9/2032 | U23: تم تغيير العنوان 17929 في 11/3/2024 26994في 2024/4/21
A24: 22 | B24: مصطفى مبدر عبدالهادي عباس العزاوي | C24: معاون مهندس تقني | D24: 7 | E24: 1 | F24: 296 | G24: 2 | H24: 302 | I24: 44909 | J24: 45213 | K24: 2 | L24: 6240 3/9/2023 17929 في 11/3/2024 | U24: تم تغيير العنوان
A25: 23 | B25: منهل فاضل ناجي كاظم الجبوري | C25: معاون مهندس تقني | D25: 7 | E25: 1 | F25: 296 | G25: 2 | H25: 302 | I25: 44909 | J25: 45244 | K25: 1 | L25: 17929 في 11/3/2024 | U25: تم تغيير العنوان
A26: 24 | B26: وليد عبدالقادر فهد حمود الشيخلي | C26: معاون مهندس تقني | D26: 7 | E26: 1 | F26: 296 | G26: 2 | H26: 302 | I26: 44909 | J26: 45213 | K26: 2 | L26: 7491 16/10/2023 17929 في 11/3/2024 | U26: تم تغيير عنوانه
A27: 25 | B27: ياسر طلال عبود بداي الساعدي | C27: معاون محاسب | D27: 7 | E27: 1 | F27: 296 | G27: 2 | H27: 302 | I27: 44909 | J27: 45213 | K27: 2 | L27: 2283 16/4/2023 17929 في 11/3/2024 | U27: تم تغيير العنوان
A28: 26 | B28: محمد محمود عبدالله محسن العزاوي | C28: فني | D28: 8 | E28: 1 | F28: 260 | G28: 2 | H28: 263 | I28: 44909 | J28: 45426 | K28: 1 | L28: 2785 26/4/2023 | R28: 1 | U28: عقوبة انذار
A29: 27 | B29: هبة طه فتحي عبود النوبان | C29: كاتب | D29: 8 | E29: 1 | F29: 260 | G29: 2 | H29: 263 | I29: 44909 | J29: 45213 | K29: 2 | L29: 2237 12/4/2023 3826 6/6/2023 | U29: تم تغيير العنوان 17929 في 2024/3/11 26994في 11/3/2024 26995في 2024/4/21
A30: 28 | B30: زهراء صاحب جارة جاسم الجابري | C30: كاتب | D30: 8 | E30: 5 | F30: 272 | G30: 6 | H30: 275 | I30: 45160 | J30: 45434 | K30: 3 | L30: 4870 23/7/2023 2237 12/4/2023 17929 في 11/3/2024
A31: 29 | B31: هديل خالد غريب محمد حسين | C31: حرفي اول | D31: 9 | E31: 1 | F31: 210 | G31: 2 | H31: 213 | I31: 44909 | J31: 45426 | K31: 1 | L31: 2237 12/4/2023 | R31: 1 | U31: عقوبة انذار
A32: 30 | B32: احمد منصور حسون عبدالسيد التميمي | C32: حرفي | D32: 10 | E32: 2 | F32: 173 | G32: 3 | H32: 176 | I32: 45094 | J32: 45429 | K32: 1 | L32: 17929 في 11/3/2024
A33: 31 | B33: حسن عبيس علوان عيفان الحيلاني | C33: حرفي | D33: 10 | E33: 2 | F33: 173 | G33: 3 | H33: 176 | I33: 45092 | J33: 45427 | K33: 1 | L33: 17929 في 11/3/2024
A34: 32 | B34: حسن نجيب عبدالحسن محمد علي الانباري | C34: حرفي | D34: 10 | E34: 2 | F34: 173 | G34: 3 | H34: 176 | I34: 45091 | J34: 45426 | K34: 1 | L34: 17929 في 11/3/2024
A35: 33 | B35: حسين حسن علوان عيفان الحيلان | C35: حرفي | D35: 10 | E35: 2 | F35: 173 | G35: 3 | H35: 176 | I35: 45091 | J35: 45426 | K35: 1 | L35: 17929 في 11/3/2024
A36: 34 | B36: حسين رحيم فليح حسن السعيدي | C36: حرفي | D36: 10 | E36: 2 | F36: 173 | G36: 3 | H36: 176 | I36: 45094 | J36: 45429 | K36: 1 | L36: 17929 في 11/3/2024
A37: 35 | B37: حسين عبدالكريم سلمان حمادي الحيالي | C37: حرفي | D37: 10 | E37: 2 | F37: 173 | G37: 3 | H37: 176 | I37: 45092 | J37: 45427 | K37: 1 | L37: 17929 في 11/3/2024
A38: 36 | B38: حيدر منصور حسون عبدالسيد | C38: حرفي | D38: 10 | E38: 2 | F38: 173 | G38: 3 | H38: 176 | I38: 45100 | J38: 45435 | K38: 1 | L38: 17929 في 11/3/2024
A39: 37 | B39: رحيم حرز كاطع حميد الكعبي | C39: حرفي | D39: 10 | E39: 2 | F39: 173 | G39: 3 | H39: 176 | I39: 45091 | J39: 45426 | K39: 1 | L39: 17929 في 11/3/2024
A40: 38 | B40: صالح كامل صالح حسن الركابي | C40: حرفي | D40: 10 | E40: 2 | F40: 173 | G40: 3 | H40: 176 | I40: 45102 | J40: 45437 | K40: 1 | L40: 17929 في 11/3/2024
...

Sheet علاوات ملاك قديم عام 2024
A1: جدول مستحقي العلاوات لشهر اذار محطة كهرباء الشهيد علي سبع
A2: ت | B2: الاسم الثلاثي | C2: العنوان الوظيفي | D2: الدرجة | E2: المرحلة القديمة | F2: الراتب القديم | G2: المرحلة الجديدة | H2: الراتب الجديد | I2: تاريخ الاستحقاق القديم | J2: تاريخ الاستحقاق الجديد | K2: كتب الشكر | L2: رقم وتاريخ كتب الشكر | M2: خدمة المدورة | P2: اجازة بدون راتب / غيابات | Q2: لفت نظر / امومة | R2: انذار | S2: توبيخ | T2: رقم وتاريخ العقوبات | U2: الملاحضات
M3: يوم | N3: شهر | O3: سنة
A4: 1 | B4: عصام محسن محمود صالح الموسوي | C4: رئيس مهندسين تقني اقدم | D4: 2 | E4: 18 | F4: 1033 | G4: 19 | H4: 1053 | I4: 44990 | J4: 45327 | K4: 1 | L4: 17929 في 11/3/2024
A5: 2 | B5: داود سلمان جبر راضي البديري | C5: معاون مدير فني | D5: 4 | E5: 2 | F5: 517 | G5: 3 | H5: 525 | I5: 45027 | J5: 45333 | K5: 2 | L5: 17929 في 11/3/2024 404 في 15/1/2024
A6: 3 | B6: قدس احمد فارس منيشن الساعدي | C6: معاون رئيس مهندسين | D6: 4 | E6: 1 | F6: 509 | G6: 2 | H6: 517 | I6: 45004 | J6: 45341 | K6: 1 | L6: 17929 في 11/3/2024
A7: 4 | B7: احمد هيثم نافع العاني | C7: معاون مدير فني | D7: 4 | E7: 1 | F7: 509 | G7: 2 | H7: 517 | I7: 45029 | J7: 45364 | K7: 1 | L7: 17929 في 11/3/2024
A8: 5 | B8: اسراء علي حسين ظاهر الجبوري | C8: معاون مدير حسابات | D8: 4 | E8: 4 | F8: 533 | G8: 5 | H8: 541 | I8: 45074 | J8: 45379 | K8: 2 | L8: 17929 في 11/3/2024 269 في 10/1/2024
A9: 6 | B9: رعد مديح جميل محمد النعيمي | C9: معاون مدير فني | D9: 4 | E9: 10 | F9: 581 | G9: 11 | H9: 589 | I9: 45074 | J9: 45379 | K9: 2 | L9: 17929 في 11/3/2024 296 في 10/1/2024
A10: 7 | B10: براق اسماعيل محمد ابرهيم | C10: رئيس ملاحظين | D10: 5 | E10: 2 | F10: 435 | G10: 3 | H10: 441 | I10: 45221 | J10: 45346 | K10: 1 | L10: 17929 في 11/3/2024 | M10: 1 | N10: 7
A11: 8 | B11: حامد حسين بكر حسين | C11: رئيس ملاحظين فني | D11: 5 | E11: 3 | F11: 441 | G11: 4 | H11: 447 | I11: 45010 | J11: 45347 | K11: 1 | L11: 17929 في 11/3/2024
A12: 9 | B12: حيدر ابراهيم مراد علي | C12: مهندس تقني اقدم | D12: 5 | E12: 3 | F12: 441 | G12: 4 | H12: 447 | I12: 44986 | J12: 45323 | K12: 1 | L12: 17929 في 11/3/2024
A13: 10 | B13: رائد شاكر حافظ جلاب الساعدي | C13: رئيس ملاحظين | D13: 5 | E13: 1 | F13: 429 | G13: 2 | H13: 435 | I13: 45237 | J13: 45340 | K13: 1 | L13: 17929 في 11/3/2024 | M13: 22 | N13: 7
A14: 11 | B14: قصي طه نايف عباس | C14: رئيس ملاحظين فني | D14: 5 | E14: 1 | F14: 429 | G14: 2 | H14: 435 | I14: 45237 | J14: 45345 | K14: 1 | L14: 17929 في 11/3/2024 | M14: 17 | N14: 7
A15: 12 | B15: منذر مهدي حمودي منصور | C15: رئيس ملاحظين | D15: 5 | E15: 3 | F15: 441 | G15: 4 | H15: 447 | I15: 45221 | J15: 45327 | K15: 1 | L15: 17929 في 11/3/2024 | M15: 20 | N15: 7
A16: 13 | B16: نور طه نصيف عبداللطيف | C16: رئيس ملاحظين | D16: 5 | E16: 3 | F16: 441 | G16: 4 | H16: 447 | I16: 45008 | J16: 45345 | K16: 1 | L16: 17929 في 11/3/2024 404 في 15/1/2024
A17: 14 | B17: بشار ابراهيم عبدالله جزاع | C17: رئيس ملاحظين فني | D17: 5 | E17: 1 | F17: 429 | G17: 2 | H17: 435 | I17: 45237 | J17: 45375 | K17: 1 | L17: 17929 في 11/3/2024 | M17: 17 | N17: 6
A18: 15 | B18: سناء وليد احمد سلمان | C18: رئيس ملاحظين | D18: 5 | E18: 3 | F18: 441 | G18: 4 | H18: 447 | I18: 45033 | J18: 45368 | K18: 1 | L18: 17929 في 11/3/2024
A19: 16 | B19: عبدالعظيم ياسين طه حسن | C19: محاسب اقدم | D19: 5 | E19: 4 | F19: 447 | G19: 5 | H19: 453 | I19: 45028 | J19: 45363 | K19: 1 | L19: 17929 في 11/3/2024
A20: 17 | B20: علي محمد عبدالجبار زيدان | C20: رئيس ملاحظين | D20: 5 | E20: 3 | F20: 441 | G20: 4 | H20: 447 | I20: 45024 | J20: 45359 | K20: 1 | L20: 17929 في 11/3/2024
A21: 18 | B21: فائز كامل عبدالله حسين | C21: رئيس ملاحظين فني | D21: 5 | E21: 3 | F21: 441 | G21: 4 | H21: 447 | I21: 45221 | J21: 45360 | K21: 1 | L21: 17929 في 11/3/2024 | M21: 17 | N21: 6
A22: 19 | B22: كوثر جبار علي خضير الدراجي | C22: رئيس حرفيين أقدم | D22: 5 | E22: 7 | F22: 465 | G22: 8 | H22: 471 | I22: 45039 | J22: 45374 | K22: 1 | L22: 17929 في 11/3/2024
A23: 20 | B23: مهند علي عبدالكريم مجيد | C23: رئيس ملاحظين فني | D23: 5 | E23: 2 | F23: 435 | G23: 3 | H23: 441 | I23: 45028 | J23: 45363 | K23: 1 | L23: 17929 في 11/3/2024
A24: 21 | B24: مهند هلال ثويني حمزه | C24: مهندس تقني اقدم | D24: 5 | E24: 3 | F24: 441 | G24: 4 | H24: 447 | I24: 45044 | J24: 45379 | K24: 1 | L24: 17929 في 11/3/2024
A25: 22 | B25: نصير قدوري احمد عكلة الدليمي | C25: رئيس حرفيين اقدم | D25: 5 | E25: 3 | F25: 441 | G25: 4 | H25: 447 | I25: 45027 | J25: 45362 | K25: 1 | L25: 17929 في 11/3/2024
A26: 23 | B26: امير محمد حامد احمد النقيب | C26: ملاحظ فني | D26: 6 | E26: 3 | F26: 374 | G26: 4 | H26: 380 | I26: 44994 | J26: 45331 | K26: 1 | L26: 17929 في 11/3/2024
A27: 24 | B27: اوس حسام جواد علي | C27: ملاحظ فني | D27: 6 | E27: 1 | F27: 362 | G27: 2 | H27: 368 | I27: 45017 | J27: 45323 | K27: 2 | L27: 17929 في 11/3/2024 404 في 15/1/2024
A28: 25 | B28: حسن اثير حكمت مجيد | C28: ملاحظ | D28: 6 | E28: 3 | F28: 374 | G28: 4 | H28: 380 | I28: 45006 | J28: 45343 | K28: 1 | L28: 17929 في 11/3/2024
A29: 26 | B29: حسنين عماد هاشم محمد صالح | C29: مهندس | D29: 6 | E29: 3 | F29: 374 | G29: 4 | H29: 380 | I29: 45031 | J29: 45337 | K29: 2 | L29: 17929 في 11/3/2024 617 في 21/1/2024
A30: 27 | B30: سيف عبدالكريم بلبول مطر | C30: رئيس حرفيين | D30: 6 | E30: 2 | F30: 368 | G30: 3 | H30: 374 | I30: 44998 | J30: 45335 | K30: 1 | L30: 17929 في 11/3/2024
A31: 28 | B31: صديق محمود جبار ابراهيم | C31: ملاحظ فني | D31: 6 | E31: 3 | F31: 374 | G31: 4 | H31: 380 | I31: 45010 | J31: 45347 | K31: 1 | L31: 17929 في 11/3/2024
A32: 29 | B32: محمد عماد خليل ابراهيم | C32: مهندس تقني | D32: 6 | E32: 3 | F32: 374 | G32: 4 | H32: 380 | I32: 44991 | J32: 45328 | K32: 1 | L32: 17929 في 11/3/2024
A33: 30 | B33: حسين علي محمد سعيد | C33: رئيس حرفيين | D33: 6 | E33: 1 | F33: 362 | G33: 2 | H33: 368 | I33: 45029 | J33: 45364 | K33: 1 | L33: 17929 في 11/3/2024
... A36: 33 | B36: قصي محمد سالم عبدالرزاق العكيلي | C36: رئيس حرفيين | D36: 6 | E36: 2 | F36: 368 | G36: 3 | H36: 374 | I36: 45029 | J36: 45364 | K36: 1 | L36: 17929 في 11/3/2024
A37: 34 | B37: احمد مؤيد اسماعيل خيرو النعيمي | C37: معاون رئيس سواق | D37: 7 | E37: 1 | F37: 296 | G37: 2 | H37: 302 | I37: 45237 | J37: 45346 | K37: 1 | L37: 17929 في 11/3/2024 | M37: 16 | N37: 7
A38: 35 | B38: عادل حميد كاظم سرداح | C38: معاون رئيس حرفيين | D38: 7 | E38: 3 | F38: 308 | G38: 4 | H38: 314 | I38: 45171 | J38: 45324 | K38: 7 | L38: 17929 في 11/3/2024 9106 في 6/12/2023
A39: 36 | B39: فاضل عباس شلال محمد | C39: معاون رئيس حرفيين | D39: 7 | E39: 3 | F39: 308 | G39: 4 | H39: 314 | I39: 45015 | J39: 45351 | K39: 1 | L39: 17929 في 11/3/2024
A40: 37 | B40: اسماء هاشم طاهر | C40: معاون رئيس حرفيين | D40: 7 | E40: 3 | F40: 308 | G40: 4 | H40: 314 | I40: 45059 | J40: 45364 | K40: 2 | L40: 17929 في 11/3/2024 6240 في 3/9/2023
A41: 38 | B41: عبدالله علي حسين احمد | C41: معاون رئيس حرفيين | D41: 7 | E41: 3 | F41: 308 | G41: 4 | H41: 314 | I41: 45060 | J41: 45365 | K41: 2 | L41: 17929 في 11/3/2024 404 في 15/1/2024
A42: 39 | B42: مهران عباس محمد محسن | C42: معاون رئيس حرفيين | D42: 7 | E42: 3 | F42: 308 | G42: 4 | H42: 314 | I42: 45023 | J42: 45358 | K42: 1 | L42: 17929 في 11/3/2024
...

Sheet علاوات ياسر اكرم
A1: ت | B1: الاسم الرباعي | C1: العنوان الوظيفي | D1: التحصيل الدراسي | E1: الدرجة | F1: المرحلة القديمة | G1: الراتب القديم | H1: المرحلة الجديدة | I1: الراتب الجديد | J1: تاريخ الاستحقاق القديم | K1: تاريخ الاستحقاق الجديد | L1: كتب الشكر | M1: رقم وتاريخ كتب الشكر
A4: 1 | B4: ياسر اكرم داود سلمان القيسي | C4: رئيس مهندسين اقدم اول | D4: بكالوريوس هندسة ميكانيك | E4: 1 | F4: 1 | G4: 910 | H4: 2 | I4: 930 | J4: 45530 | K4: 45652 | L4: 8 | M4: 18526في 14/4/2025 4912 في 27/1/2025 11781في 27/2/2025
A5: 2 | B5: علاء حسين مكطوف الدراجي | C5: معاون رئيس سواق | D5: ابتدائية | E5: 7 | F5: 3 | G5: 308 | H5: 4 | I5: 314 | J5: 45523 | K5: 45676 | L5: 7 | M5: 14442في 13/3/2025 18526في 14/4/2025

Sheet ورقة2
A1: ت | B1: الاسم الرباعي | C1: العنوان الوظيفي | D1: التحصيل الدراسي | E1: الدرجة | F1: المرحلة القديمة | G1: الراتب القديم | H1: المرحلة الجديدة | I1: الراتب الجديد | J1: تاريخ الاستحقاق القديم | K1: تاريخ الاستحقاق الجديد | L1: تنبيه العلاوة | M1: كتب الشكر | N1: رقم وتاريخ كتب الشكر | O1: خدمة المدورة | R1: اجازة بدون راتب / غيابات | S1: لفت نظر / امومة | T1: انذار | U1: توبيخ | V1: رقم وتاريخ العقوبات | W1: الملاحضات | X1: نوع الملاك | Y1: الجنس
O2: يوم | P2: شهر | Q2: سنة
A4: 1 | B4: داود سلمان جبر راضي البديري | C4: معاون مدير فني | D4: اعدادية كهرباء | E4: 4 | F4: 5 | G4: 541 | H4: 6 | I4: 549 | J4: 45637 | K4: 46002 | W4: مفوضية | X4: ملاك قديم | Y4: ذكر
